Workbook

Sheet README
A1: PTSC 27-Run Master Results Workbook
A3: Purpose: one workbook tracking every one of the 27 Taguchi production runs, plus the
A4: Baseline reference run (smooth tube, plain Syltherm 800, same Re/Tin), from geometry
A5: and mesh inputs through to final performance results.
A7: Adopted mesh (locked, per mesh-independence study): 2.96 mm global element size,
A8: same inflation settings used throughout mesh-validation. See thesis/mesh-validation/gci_mesh_plan.md.
A9: Fixed conditions for all 27 runs + Baseline: Re = 10,000, Tin = 500 K, Tube length = 2000 mm (2 m),
A10: dti = 66 mm, dto = 70 mm. See thesis/notes/decision_log.md for how these were decided.
A12: Sheet guide:
A13: 1. Run Matrix (Inputs) -- geometry, nanofluid, concentration, Re/Tin. Fully pre-filled, locked.
A14: 2. Mesh Outputs -- element size, element/node count, quality metrics. Fill in as each mesh is generated.
A15: 3. Fluid Properties (computed) -- hybrid nanofluid rho/Cp/k/mu, computed from mixing-rule formulas.
... A32: Always type the POSITIVE magnitude into mdot_out, or the mass-balance-error formula breaks.

Sheet Constants
A1: Constants & Property Reference
A3: Fixed geometry / operating conditions
A4: d_ri | B4: Absorber tube inner diameter | C4: 0.066 | D4: m
A5: d_ro | B5: Absorber tube outer diameter | C5: 0.07 | D5: m
A6: L_tube | B6: Tube length (2 m, this study's length decision) | C6: 2 | D6: m
A7: Re_target | B7: Fixed Reynolds number, all 27 runs + baseline | C7: 10000 | D7: -
A8: T_in | B8: Fixed inlet temperature, all 27 runs + baseline | C8: 500 | D8: K
A9: A_a | B9: Collector aperture area (LS-2) | C9: 39.2 | D9: m^2
A10: I_b | B10: Direct normal irradiance (DNI) | C10: 1000 | D10: W/m^2
A11: T_amb | B11: Ambient temperature | C11: 300 | D11: K
A12: T_s | B12: Apparent sun temperature | C12: 5800 | D12: K
A13: eta_el | B13: Mechanical-to-electrical pump efficiency factor | C13: 0.3 | D13: -
A15: Brick-shape nanofluid mixing coefficients (CORRECTED from the real Mohammed et al. 2022 paper's own Table 7/8 -- see decision_log.md)
A16: Ck | B16: Thermal conductivity shape coefficient (bricks) | C16: 3.37 | D16: -
A17: a_visc | B17: Viscosity morphology constant a (bricks) | C17: 1.9 | D17: -
A18: b_visc | B18: Viscosity morphology constant b (bricks) | C18: 471.4 | D18: -
A20: Syltherm 800 base fluid properties AT Tin=500K -- PLACEHOLDER, fill in yellow cells
E21: NOT YET CONFIRMED -- Table 6 values from Mohammed et al. 2022 are reference/room-temp values, NOT necessarily at 500K. Read the real values off Fluent's Material panel once Syltherm 800 is entered with its temperature-dependent polynomial (Fluent Setup step), or from the Dow datasheet once available. Using the room-temp reference numbers below as placeholders only -- replace before trusting any Nu/f/eta result.
A22: rho_bf | B22: Syltherm 800 density at Tin | C22: 747.2 | D22: kg/m^3
A23: Cp_bf | B23: Syltherm 800 specific heat at Tin | C23: 1962 | D23: J/kg.K
A24: k_bf | B24: Syltherm 800 thermal conductivity at Tin | C24: 0.0961 | D24: W/m.K
A25: mu_bf | B25: Syltherm 800 viscosity at Tin | C25: 0.00084 | D25: Pa.s
A27: Nanoparticle properties (fill in Al2O3, MWCNT, Ag, MgO rows once sourced -- open item, decision_log.md)
A28: Particle | B28: Density rho_p (kg/m3) | C28: Specific heat Cp_p (J/kg.K) | D28: Source
A29: Fe2O3 | B29: 5180 | C29: 670 | D29: Mohammed et al. 2022 Table 6 (real paper, verified)
A30: GO | B30: 1800 | C30: 717 | D30: Mohammed et al. 2022 Table 6 (real paper, verified)
A31: Al2O3 | D31: NOT YET SOURCED
A32: MWCNT | D32: NOT YET SOURCED
A33: Ag | D33: NOT YET SOURCED
A34: MgO | D34: NOT YET SOURCED

Sheet Run Matrix (Inputs)
A1: Run | B1: A (Pt/dti) | C1: B (dpo/dti) | D1: C (tp/dpo) | E1: Nanofluid | F1: Particle1 | G1: Particle2 | H1: phi (%) | I1: Pt (mm) | J1: dpo (mm) | K1: tp (mm) | L1: dpi (mm) | M1: Tube length (mm) | N1: Re | O1: Tin (K)
A2: Baseline | E2: Syltherm 800 (no nanoparticles, smooth tube) | H2: 0 | I2: - | J2: - | K2: - | L2: - | M2: 2000 | N2: =Constants!$C$7 -> 10000 | O2: =Constants!$C$8 -> 500
A3: 1 | B3: 3.03 | C3: 0.23 | D3: 0.04 | E3: Fe2O3-GO | F3: Fe2O3 | G3: GO | H3: 0.5 | I3: 200 | J3: 15 | K3: 0.6 | L3: 13.8 | M3: 2000 | N3: =Constants!$C$7 -> 10000 | O3: =Constants!$C$8 -> 500
A4: 2 | B4: 3.03 | C4: 0.23 | D4: 0.08 | E4: Al2O3-MWCNT | F4: Al2O3 | G4: MWCNT | H4: 1 | I4: 200 | J4: 15 | K4: 1.2 | L4: 12.6 | M4: 2000 | N4: =Constants!$C$7 -> 10000 | O4: =Constants!$C$8 -> 500
A5: 3 | B5: 3.03 | C5: 0.23 | D5: 0.12 | E5: Ag-MgO | F5: Ag | G5: MgO | H5: 2 | I5: 200 | J5: 15 | K5: 1.8 | L5: 11.4 | M5: 2000 | N5: =Constants!$C$7 -> 10000 | O5: =Constants!$C$8 -> 500
A6: 4 | B6: 3.03 | C6: 0.38 | D6: 0.04 | E6: Al2O3-MWCNT | F6: Al2O3 | G6: MWCNT | H6: 2 | I6: 200 | J6: 25 | K6: 1 | L6: 23 | M6: 2000 | N6: =Constants!$C$7 -> 10000 | O6: =Constants!$C$8 -> 500
A7: 5 | B7: 3.03 | C7: 0.38 | D7: 0.08 | E7: Ag-MgO | F7: Ag | G7: MgO | H7: 0.5 | I7: 200 | J7: 25 | K7: 2 | L7: 21 | M7: 2000 | N7: =Constants!$C$7 -> 10000 | O7: =Constants!$C$8 -> 500
A8: 6 | B8: 3.03 | C8: 0.38 | D8: 0.12 | E8: Fe2O3-GO | F8: Fe2O3 | G8: GO | H8: 1 | I8: 200 | J8: 25 | K8: 3 | L8: 19 | M8: 2000 | N8: =Constants!$C$7 -> 10000 | O8: =Constants!$C$8 -> 500
A9: 7 | B9: 3.03 | C9: 0.53 | D9: 0.04 | E9: Ag-MgO | F9: Ag | G9: MgO | H9: 1 | I9: 200 | J9: 35 | K9: 1.4 | L9: 32.2 | M9: 2000 | N9: =Constants!$C$7 -> 10000 | O9: =Constants!$C$8 -> 500
A10: 8 | B10: 3.03 | C10: 0.53 | D10: 0.08 | E10: Fe2O3-GO | F10: Fe2O3 | G10: GO | H10: 2 | I10: 200 | J10: 35 | K10: 2.8 | L10: 29.4 | M10: 2000 | N10: =Constants!$C$7 -> 10000 | O10: =Constants!$C$8 -> 500
A11: 9 | B11: 3.03 | C11: 0.53 | D11: 0.12 | E11: Al2O3-MWCNT | F11: Al2O3 | G11: MWCNT | H11: 0.5 | I11: 200 | J11: 35 | K11: 4.2 | L11: 26.6 | M11: 2000 | N11: =Constants!$C$7 -> 10000 | O11: =Constants!$C$8 -> 500
A12: 10 | B12: 4.55 | C12: 0.23 | D12: 0.04 | E12: Al2O3-MWCNT | F12: Al2O3 | G12: MWCNT | H12: 1 | I12: 300 | J12: 15 | K12: 0.6 | L12: 13.8 | M12: 2000 | N12: =Constants!$C$7 -> 10000 | O12: =Constants!$C$8 -> 500
A13: 11 | B13: 4.55 | C13: 0.23 | D13: 0.08 | E13: Ag-MgO | F13: Ag | G13: MgO | H13: 2 | I13: 300 | J13: 15 | K13: 1.2 | L13: 12.6 | M13: 2000 | N13: =Constants!$C$7 -> 10000 | O13: =Constants!$C$8 -> 500
A14: 12 | B14: 4.55 | C14: 0.23 | D14: 0.12 | E14: Fe2O3-GO | F14: Fe2O3 | G14: GO | H14: 0.5 | I14: 300 | J14: 15 | K14: 1.8 | L14: 11.4 | M14: 2000 | N14: =Constants!$C$7 -> 10000 | O14: =Constants!$C$8 -> 500
... A29: 27 | B29: 6.06 | C29: 0.53 | D29: 0.12 | E29: Fe2O3-GO | F29: Fe2O3 | G29: GO | H29: 2 | I29: 400 | J29: 35 | K29: 4.2 | L29: 26.6 | M29: 2000 | N29: =Constants!$C$7 -> 10000 | O29: =Constants!$C$8 -> 500

Sheet Mesh Outputs
A1: Run | B1: Element size (mm) | C1: Elements | D1: Nodes | E1: Max Skewness | F1: Min Orthogonal Quality | G1: Notes
A2: Baseline
A3: 1 | B3: 2.96 | C3: 3991036 | D3: 1636945 | E3: 0.84954 | F3: 0.015272 | G3: Element size matches adopted Mesh 3 (2.96mm). Skewness/orthogonal quality land in the same range as the mesh-independence study (~0.85 / ~0.015) -- confirms the smaller promoter (dpo=15mm) did not degrade mesh quality despite the narrower core passage.
A4: 2
A5: 3
A6: 4
A7: 5
A8: 6 | B8: 2.96 | C8: 5032279 | D8: 1869731 | E8: 0.84882 | F8: 0.010296 | G8: Min Orthogonal Quality right at the 0.01 edge (barely clears) - watch item for larger-promoter runs.
A9: 7
A10: 8 | B10: 2.96 | C10: 6293136 | D10: 2404391 | E10: 0.84882 | F10: 0.0096914 | G10: INVALID - Min Orthogonal Quality 0.0096914 below 0.01 threshold (Max Aspect Ratio 959.99, near ANSYS failure limit 1000). Solution diverged. Needs finer local mesh in tight annulus region (dpo=35mm, tightest gap of any run tested) before re-running.
A11: 9
A12: 10
A13: 11
A14: 12 | B14: 2.96 | C14: 4378599 | D14: 1625862 | E14: 0.84954 | F14: 0.016175 | G14: Clean mesh, well above 0.01 quality target.
A15: 13
A16: 14
A17: 15
A18: 16 | B18: 2.96 | C18: 6054475 | D18: 2334551 | E18: 0.84954 | F18: 0.0092812 | G18: INVALID - same failure as Run 8: Min Orthogonal Quality 0.0092812, below 0.01 threshold. Solution diverged (T_wall=4925K, p_in~2.7e35). CONFIRMED PATTERN: Run 8 and Run 16 both use dpo=35mm (largest promoter, tightest annulus, ~15.5mm gap) - this geometry level needs finer local mesh before re-running. Run 27 (also dpo=35mm) is at high risk of the same failure.
A19: 17
A20: 18
A21: 19
A22: 20
A23: 21
A24: 22
A25: 23
A26: 24
A27: 25
A28: 26
A29: 27

Sheet Fluid Properties
A1: Run | B1: phi1 (=phi2, even-split assumption) | C1: rho_p1 | D1: Cp_p1 | E1: rho_p2 | F1: Cp_p2 | G1: rho_hnf (kg/m3) | H1: Cp_hnf (J/kg.K) | I1: k_hnf (W/m.K) | J1: mu_hnf (Pa.s)
A2: Baseline | B2: 0 | G2: =Constants!$C$22 -> 747.2 | H2: =Constants!$C$23 -> 1962 | I2: =Constants!$C$24 -> 0.0961 | J2: =Constants!$C$25 -> 0.00084
A3: 1 | B3: ='Run Matrix (Inputs)'!$H$3/100/2 -> 0.0025 | C3: =IF(IFERROR(INDEX(Constants!$B$29:$B$34,MATCH('Run Matrix (Inputs)'!$F$3,Constants!$A$29:$A$34,0)),"")="","",IFERROR(INDEX(Constants!$B$29:$B$34,MATCH('Run Matrix (Inputs)'!$F$3,Constants!$A$29:$A$34,0)),"")) -> 5180 | D3: =IF(IFERROR(INDEX(Constants!$C$29:$C$34,MATCH('Run Matrix (Inputs)'!$F$3,Constants!$A$29:$A$34,0)),"")="","",IFERROR(INDEX(Constants!$C$29:$C$34,MATCH('Run Matrix (Inputs)'!$F$3,Constants!$A$29:$A$34,0)),"")) -> 670 | E3: =IF(IFERROR(INDEX(Constants!$B$29:$B$34,MATCH('Run Matrix (Inputs)'!$G$3,Constants!$A$29:$A$34,0)),"")="","",IFERROR(INDEX(Constants!$B$29:$B$34,MATCH('Run Matrix (Inputs)'!$G$3,Constants!$A$29:$A$34,0)),"")) -> 1800 | F3: =IF(IFERROR(INDEX(Constants!$C$29:$C$34,MATCH('Run Matrix (Inputs)'!$G$3,Constants!$A$29:$A$34,0)),"")="","",IFERROR(INDEX(Constants!$C$29:$C$34,MATCH('Run Matrix (Inputs)'!$G$3,Constants!$A$29:$A$34,0)),"")) -> 717 | G3: =IF(OR($C$3="",$E$3=""),"",(1-'Run Matrix (Inputs)'!$H$3/100)*Constants!$C$22+$B$3*$C$3+$B$3*$E$3) -> 760.914 | H3: =IF(OR(OR($C$3="",$E$3=""),$G$3=""),"",((1-'Run Matrix (Inputs)'!$H$3/100)*Constants!$C$22*Constants!$C$23+$B$3*$C$3*$D$3+$B$3*$E$3*$F$3)/$G$3) -> 1932.6486 | I3: =Constants!$C$24*(1+Constants!$C$16*'Run Matrix (Inputs)'!$H$3/100) -> 0.097719285 | J3: =Constants!$C$25*((1+Constants!$C$17*$B$3+Constants!$C$18*$B$3^2)+(1+Constants!$C$17*$B$3+Constants!$C$18*$B$3^2)) -> 0.0016929297
A4: 2 | B4: ='Run Matrix (Inputs)'!$H$4/100/2 -> 0.005 | C4: =IF(IFERROR(INDEX(Constants!$B$29:$B$34,MATCH('Run Matrix (Inputs)'!$F$4,Constants!$A$29:$A$34,0)),"")="","",IFERROR(INDEX(Constants!$B$29:$B$34,MATCH('Run Matrix (Inputs)'!$F$4,Constants!$A$29:$A$34,0)),"")) | D4: =IF(IFERROR(INDEX(Constants!$C$29:$C$34,MATCH('Run Matrix (Inputs)'!$F$4,Constants!$A$29:$A$34,0)),"")="","",IFERROR(INDEX(Constants!$C$29:$C$34,MATCH('Run Matrix (Inputs)'!$F$4,Constants!$A$29:$A$34,0)),"")) | E4: =IF(IFERROR(INDEX(Constants!$B$29:$B$34,MATCH('Run Matrix (Inputs)'!$G$4,Constants!$A$29:$A$34,0)),"")="","",IFERROR(INDEX(Constants!$B$29:$B$34,MATCH('Run Matrix (Inputs)'!$G$4,Constants!$A$29:$A$34,0)),"")) | F4: =IF(IFERROR(INDEX(Constants!$C$29:$C$34,MATCH('Run Matrix (Inputs)'!$G$4,Constants!$A$29:$A$34,0)),"")="","",IFERROR(INDEX(Constants!$C$29:$C$34,MATCH('Run Matrix (Inputs)'!$G$4,Constants!$A$29:$A$34,0)),"")) | G4: =IF(OR($C$4="",$E$4=""),"",(1-'Run Matrix (Inputs)'!$H$4/100)*Constants!$C$22+$B$4*$C$4+$B$4*$E$4) | H4: =IF(OR(OR($C$4="",$E$4=""),$G$4=""),"",((1-'Run Matrix (Inputs)'!$H$4/100)*Constants!$C$22*Constants!$C$23+$B$4*$C$4*$D$4+$B$4*$E$4*$F$4)/$G$4) | I4: =Constants!$C$24*(1+Constants!$C$16*'Run Matrix (Inputs)'!$H$4/100) -> 0.09933857 | J4: =Constants!$C$25*((1+Constants!$C$17*$B$4+Constants!$C$18*$B$4^2)+(1+Constants!$C$17*$B$4+Constants!$C$18*$B$4^2)) -> 0.0017157588
A5: 3 | B5: ='Run Matrix (Inputs)'!$H$5/100/2 -> 0.01 | C5: =IF(IFERROR(INDEX(Constants!$B$29:$B$34,MATCH('Run Matrix (Inputs)'!$F$5,Constants!$A$29:$A$34,0)),"")="","",IFERROR(INDEX(Constants!$B$29:$B$34,MATCH('Run Matrix (Inputs)'!$F$5,Constants!$A$29:$A$34,0)),"")) | D5: =IF(IFERROR(INDEX(Constants!$C$29:$C$34,MATCH('Run Matrix (Inputs)'!$F$5,Constants!$A$29:$A$34,0)),"")="","",IFERROR(INDEX(Constants!$C$29:$C$34,MATCH('Run Matrix (Inputs)'!$F$5,Constants!$A$29:$A$34,0)),"")) | E5: =IF(IFERROR(INDEX(Constants!$B$29:$B$34,MATCH('Run Matrix (Inputs)'!$G$5,Constants!$A$29:$A$34,0)),"")="","",IFERROR(INDEX(Constants!$B$29:$B$34,MATCH('Run Matrix (Inputs)'!$G$5,Constants!$A$29:$A$34,0)),"")) | F5: =IF(IFERROR(INDEX(Constants!$C$29:$C$34,MATCH('Run Matrix (Inputs)'!$G$5,Constants!$A$29:$A$34,0)),"")="","",IFERROR(INDEX(Constants!$C$29:$C$34,MATCH('Run Matrix (Inputs)'!$G$5,Constants!$A$29:$A$34,0)),"")) | G5: =IF(OR($C$5="",$E$5=""),"",(1-'Run Matrix (Inputs)'!$H$5/100)*Constants!$C$22+$B$5*$C$5+$B$5*$E$5) | H5: =IF(OR(OR($C$5="",$E$5=""),$G$5=""),"",((1-'Run Matrix (Inputs)'!$H$5/100)*Constants!$C$22*Constants!$C$23+$B$5*$C$5*$D$5+$B$5*$E$5*$F$5)/$G$5) | I5: =Constants!$C$24*(1+Constants!$C$16*'Run Matrix (Inputs)'!$H$5/100) -> 0.10257714 | J5: =Constants!$C$25*((1+Constants!$C$17*$B$5+Constants!$C$18*$B$5^2)+(1+Constants!$C$17*$B$5+Constants!$C$18*$B$5^2)) -> 0.0017911152
A6: 4 | B6: ='Run Matrix (Inputs)'!$H$6/100/2 -> 0.01 | C6: =IF(IFERROR(INDEX(Constants!$B$29:$B$34,MATCH('Run Matrix (Inputs)'!$F$6,Constants!$A$29:$A$34,0)),"")="","",IFERROR(INDEX(Constants!$B$29:$B$34,MATCH('Run Matrix (Inputs)'!$F$6,Constants!$A$29:$A$34,0)),"")) | D6: =IF(IFERROR(INDEX(Constants!$C$29:$C$34,MATCH('Run Matrix (Inputs)'!$F$6,Constants!$A$29:$A$34,0)),"")="","",IFERROR(INDEX(Constants!$C$29:$C$34,MATCH('Run Matrix (Inputs)'!$F$6,Constants!$A$29:$A$34,0)),"")) | E6: =IF(IFERROR(INDEX(Constants!$B$29:$B$34,MATCH('Run Matrix (Inputs)'!$G$6,Constants!$A$29:$A$34,0)),"")="","",IFERROR(INDEX(Constants!$B$29:$B$34,MATCH('Run Matrix (Inputs)'!$G$6,Constants!$A$29:$A$34,0)),"")) | F6: =IF(IFERROR(INDEX(Constants!$C$29:$C$34,MATCH('Run Matrix (Inputs)'!$G$6,Constants!$A$29:$A$34,0)),"")="","",IFERROR(INDEX(Constants!$C$29:$C$34,MATCH('Run Matrix (Inputs)'!$G$6,Constants!$A$29:$A$34,0)),"")) | G6: =IF(OR($C$6="",$E$6=""),"",(1-'Run Matrix (Inputs)'!$H$6/100)*Constants!$C$22+$B$6*$C$6+$B$6*$E$6) | H6: =IF(OR(OR($C$6="",$E$6=""),$G$6=""),"",((1-'Run Matrix (Inputs)'!$H$6/100)*Constants!$C$22*Constants!$C$23+$B$6*$C$6*$D$6+$B$6*$E$6*$F$6)/$G$6) | I6: =Constants!$C$24*(1+Constants!$C$16*'Run Matrix (Inputs)'!$H$6/100) -> 0.10257714 | J6: =Constants!$C$25*((1+Constants!$C$17*$B$6+Constants!$C$18*$B$6^2)+(1+Constants!$C$17*$B$6+Constants!$C$18*$B$6^2)) -> 0.0017911152
A7: 5 | B7: ='Run Matrix (Inputs)'!$H$7/100/2 -> 0.0025 | C7: =IF(IFERROR(INDEX(Constants!$B$29:$B$34,MATCH('Run Matrix (Inputs)'!$F$7,Constants!$A$29:$A$34,0)),"")="","",IFERROR(INDEX(Constants!$B$29:$B$34,MATCH('Run Matrix (Inputs)'!$F$7,Constants!$A$29:$A$34,0)),"")) | D7: =IF(IFERROR(INDEX(Constants!$C$29:$C$34,MATCH('Run Matrix (Inputs)'!$F$7,Constants!$A$29:$A$34,0)),"")="","",IFERROR(INDEX(Constants!$C$29:$C$34,MATCH('Run Matrix (Inputs)'!$F$7,Constants!$A$29:$A$34,0)),"")) | E7: =IF(IFERROR(INDEX(Constants!$B$29:$B$34,MATCH('Run Matrix (Inputs)'!$G$7,Constants!$A$29:$A$34,0)),"")="","",IFERROR(INDEX(Constants!$B$29:$B$34,MATCH('Run Matrix (Inputs)'!$G$7,Constants!$A$29:$A$34,0)),"")) | F7: =IF(IFERROR(INDEX(Constants!$C$29:$C$34,MATCH('Run Matrix (Inputs)'!$G$7,Constants!$A$29:$A$34,0)),"")="","",IFERROR(INDEX(Constants!$C$29:$C$34,MATCH('Run Matrix (Inputs)'!$G$7,Constants!$A$29:$A$34,0)),"")) | G7: =IF(OR($C$7="",$E$7=""),"",(1-'Run Matrix (Inputs)'!$H$7/100)*Constants!$C$22+$B$7*$C$7+$B$7*$E$7) | H7: =IF(OR(OR($C$7="",$E$7=""),$G$7=""),"",((1-'Run Matrix (Inputs)'!$H$7/100)*Constants!$C$22*Constants!$C$23+$B$7*$C$7*$D$7+$B$7*$E$7*$F$7)/$G$7) | I7: =Constants!$C$24*(1+Constants!$C$16*'Run Matrix (Inputs)'!$H$7/100) -> 0.097719285 | J7: =Constants!$C$25*((1+Constants!$C$17*$B$7+Constants!$C$18*$B$7^2)+(1+Constants!$C$17*$B$7+Constants!$C$18*$B$7^2)) -> 0.0016929297
A8: 6 | B8: 0.005 | C8: 5180 | D8: 670 | E8: 1800 | F8: 717 | G8: 774.628 | H8: 1904.3363 | I8: 0.09933857 | J8: 0.0017157588
A9: 7 | B9: ='Run Matrix (Inputs)'!$H$9/100/2 -> 0.005 | C9: =IF(IFERROR(INDEX(Constants!$B$29:$B$34,MATCH('Run Matrix (Inputs)'!$F$9,Constants!$A$29:$A$34,0)),"")="","",IFERROR(INDEX(Constants!$B$29:$B$34,MATCH('Run Matrix (Inputs)'!$F$9,Constants!$A$29:$A$34,0)),"")) | D9: =IF(IFERROR(INDEX(Constants!$C$29:$C$34,MATCH('Run Matrix (Inputs)'!$F$9,Constants!$A$29:$A$34,0)),"")="","",IFERROR(INDEX(Constants!$C$29:$C$34,MATCH('Run Matrix (Inputs)'!$F$9,Constants!$A$29:$A$34,0)),"")) | E9: =IF(IFERROR(INDEX(Constants!$B$29:$B$34,MATCH('Run Matrix (Inputs)'!$G$9,Constants!$A$29:$A$34,0)),"")="","",IFERROR(INDEX(Constants!$B$29:$B$34,MATCH('Run Matrix (Inputs)'!$G$9,Constants!$A$29:$A$34,0)),"")) | F9: =IF(IFERROR(INDEX(Constants!$C$29:$C$34,MATCH('Run Matrix (Inputs)'!$G$9,Constants!$A$29:$A$34,0)),"")="","",IFERROR(INDEX(Constants!$C$29:$C$34,MATCH('Run Matrix (Inputs)'!$G$9,Constants!$A$29:$A$34,0)),"")) | G9: =IF(OR($C$9="",$E$9=""),"",(1-'Run Matrix (Inputs)'!$H$9/100)*Constants!$C$22+$B$9*$C$9+$B$9*$E$9) | H9: =IF(OR(OR($C$9="",$E$9=""),$G$9=""),"",((1-'Run Matrix (Inputs)'!$H$9/100)*Constants!$C$22*Constants!$C$23+$B$9*$C$9*$D$9+$B$9*$E$9*$F$9)/$G$9) | I9: =Constants!$C$24*(1+Constants!$C$16*'Run Matrix (Inputs)'!$H$9/100) -> 0.09933857 | J9: =Constants!$C$25*((1+Constants!$C$17*$B$9+Constants!$C$18*$B$9^2)+(1+Constants!$C$17*$B$9+Constants!$C$18*$B$9^2)) -> 0.0017157588
A10: 8 | B10: 0.01 | C10: 5180 | D10: 670 | E10: 1800 | F10: 717 | G10: 802.056 | H10: 1850.617 | I10: 0.102577 | J10: 0.0017911
A11: 9 | B11: ='Run Matrix (Inputs)'!$H$11/100/2 -> 0.0025 | C11: =IF(IFERROR(INDEX(Constants!$B$29:$B$34,MATCH('Run Matrix (Inputs)'!$F$11,Constants!$A$29:$A$34,0)),"")="","",IFERROR(INDEX(Constants!$B$29:$B$34,MATCH('Run Matrix (Inputs)'!$F$11,Constants!$A$29:$A$34,0)),"")) | D11: =IF(IFERROR(INDEX(Constants!$C$29:$C$34,MATCH('Run Matrix (Inputs)'!$F$11,Constants!$A$29:$A$34,0)),"")="","",IFERROR(INDEX(Constants!$C$29:$C$34,MATCH('Run Matrix (Inputs)'!$F$11,Constants!$A$29:$A$34,0)),"")) | E11: =IF(IFERROR(INDEX(Constants!$B$29:$B$34,MATCH('Run Matrix (Inputs)'!$G$11,Constants!$A$29:$A$34,0)),"")="","",IFERROR(INDEX(Constants!$B$29:$B$34,MATCH('Run Matrix (Inputs)'!$G$11,Constants!$A$29:$A$34,0)),"")) | F11: =IF(IFERROR(INDEX(Constants!$C$29:$C$34,MATCH('Run Matrix (Inputs)'!$G$11,Constants!$A$29:$A$34,0)),"")="","",IFERROR(INDEX(Constants!$C$29:$C$34,MATCH('Run Matrix (Inputs)'!$G$11,Constants!$A$29:$A$34,0)),"")) | G11: =IF(OR($C$11="",$E$11=""),"",(1-'Run Matrix (Inputs)'!$H$11/100)*Constants!$C$22+$B$11*$C$11+$B$11*$E$11) | H11: =IF(OR(OR($C$11="",$E$11=""),$G$11=""),"",((1-'Run Matrix (Inputs)'!$H$11/100)*Constants!$C$22*Constants!$C$23+$B$11*$C$11*$D$11+$B$11*$E$11*$F$11)/$G$11) | I11: =Constants!$C$24*(1+Constants!$C$16*'Run Matrix (Inputs)'!$H$11/100) -> 0.097719285 | J11: =Constants!$C$25*((1+Constants!$C$17*$B$11+Constants!$C$18*$B$11^2)+(1+Constants!$C$17*$B$11+Constants!$C$18*$B$11^2)) -> 0.0016929297
A12: 10 | B12: ='Run Matrix (Inputs)'!$H$12/100/2 -> 0.005 | C12: =IF(IFERROR(INDEX(Constants!$B$29:$B$34,MATCH('Run Matrix (Inputs)'!$F$12,Constants!$A$29:$A$34,0)),"")="","",IFERROR(INDEX(Constants!$B$29:$B$34,MATCH('Run Matrix (Inputs)'!$F$12,Constants!$A$29:$A$34,0)),"")) | D12: =IF(IFERROR(INDEX(Constants!$C$29:$C$34,MATCH('Run Matrix (Inputs)'!$F$12,Constants!$A$29:$A$34,0)),"")="","",IFERROR(INDEX(Constants!$C$29:$C$34,MATCH('Run Matrix (Inputs)'!$F$12,Constants!$A$29:$A$34,0)),"")) | E12: =IF(IFERROR(INDEX(Constants!$B$29:$B$34,MATCH('Run Matrix (Inputs)'!$G$12,Constants!$A$29:$A$34,0)),"")="","",IFERROR(INDEX(Constants!$B$29:$B$34,MATCH('Run Matrix (Inputs)'!$G$12,Constants!$A$29:$A$34,0)),"")) | F12: =IF(IFERROR(INDEX(Constants!$C$29:$C$34,MATCH('Run Matrix (Inputs)'!$G$12,Constants!$A$29:$A$34,0)),"")="","",IFERROR(INDEX(Constants!$C$29:$C$34,MATCH('Run Matrix (Inputs)'!$G$12,Constants!$A$29:$A$34,0)),"")) | G12: =IF(OR($C$12="",$E$12=""),"",(1-'Run Matrix (Inputs)'!$H$12/100)*Constants!$C$22+$B$12*$C$12+$B$12*$E$12) | H12: =IF(OR(OR($C$12="",$E$12=""),$G$12=""),"",((1-'Run Matrix (Inputs)'!$H$12/100)*Constants!$C$22*Constants!$C$23+$B$12*$C$12*$D$12+$B$12*$E$12*$F$12)/$G$12) | I12: =Constants!$C$24*(1+Constants!$C$16*'Run Matrix (Inputs)'!$H$12/100) -> 0.09933857 | J12: =Constants!$C$25*((1+Constants!$C$17*$B$12+Constants!$C$18*$B$12^2)+(1+Constants!$C$17*$B$12+Constants!$C$18*$B$12^2)) -> 0.0017157588
A13: 11 | B13: ='Run Matrix (Inputs)'!$H$13/100/2 -> 0.01 | C13: =IF(IFERROR(INDEX(Constants!$B$29:$B$34,MATCH('Run Matrix (Inputs)'!$F$13,Constants!$A$29:$A$34,0)),"")="","",IFERROR(INDEX(Constants!$B$29:$B$34,MATCH('Run Matrix (Inputs)'!$F$13,Constants!$A$29:$A$34,0)),"")) | D13: =IF(IFERROR(INDEX(Constants!$C$29:$C$34,MATCH('Run Matrix (Inputs)'!$F$13,Constants!$A$29:$A$34,0)),"")="","",IFERROR(INDEX(Constants!$C$29:$C$34,MATCH('Run Matrix (Inputs)'!$F$13,Constants!$A$29:$A$34,0)),"")) | E13: =IF(IFERROR(INDEX(Constants!$B$29:$B$34,MATCH('Run Matrix (Inputs)'!$G$13,Constants!$A$29:$A$34,0)),"")="","",IFERROR(INDEX(Constants!$B$29:$B$34,MATCH('Run Matrix (Inputs)'!$G$13,Constants!$A$29:$A$34,0)),"")) | F13: =IF(IFERROR(INDEX(Constants!$C$29:$C$34,MATCH('Run Matrix (Inputs)'!$G$13,Constants!$A$29:$A$34,0)),"")="","",IFERROR(INDEX(Constants!$C$29:$C$34,MATCH('Run Matrix (Inputs)'!$G$13,Constants!$A$29:$A$34,0)),"")) | G13: =IF(OR($C$13="",$E$13=""),"",(1-'Run Matrix (Inputs)'!$H$13/100)*Constants!$C$22+$B$13*$C$13+$B$13*$E$13) | H13: =IF(OR(OR($C$13="",$E$13=""),$G$13=""),"",((1-'Run Matrix (Inputs)'!$H$13/100)*Constants!$C$22*Constants!$C$23+$B$13*$C$13*$D$13+$B$13*$E$13*$F$13)/$G$13) | I13: =Constants!$C$24*(1+Constants!$C$16*'Run Matrix (Inputs)'!$H$13/100) -> 0.10257714 | J13: =Constants!$C$25*((1+Constants!$C$17*$B$13+Constants!$C$18*$B$13^2)+(1+Constants!$C$17*$B$13+Constants!$C$18*$B$13^2)) -> 0.0017911152
A14: 12 | B14: ='Run Matrix (Inputs)'!$H$14/100/2 -> 0.0025 | C14: =IF(IFERROR(INDEX(Constants!$B$29:$B$34,MATCH('Run Matrix (Inputs)'!$F$14,Constants!$A$29:$A$34,0)),"")="","",IFERROR(INDEX(Constants!$B$29:$B$34,MATCH('Run Matrix (Inputs)'!$F$14,Constants!$A$29:$A$34,0)),"")) -> 5180 | D14: =IF(IFERROR(INDEX(Constants!$C$29:$C$34,MATCH('Run Matrix (Inputs)'!$F$14,Constants!$A$29:$A$34,0)),"")="","",IFERROR(INDEX(Constants!$C$29:$C$34,MATCH('Run Matrix (Inputs)'!$F$14,Constants!$A$29:$A$34,0)),"")) -> 670 | E14: =IF(IFERROR(INDEX(Constants!$B$29:$B$34,MATCH('Run Matrix (Inputs)'!$G$14,Constants!$A$29:$A$34,0)),"")="","",IFERROR(INDEX(Constants!$B$29:$B$34,MATCH('Run Matrix (Inputs)'!$G$14,Constants!$A$29:$A$34,0)),"")) -> 1800 | F14: =IF(IFERROR(INDEX(Constants!$C$29:$C$34,MATCH('Run Matrix (Inputs)'!$G$14,Constants!$A$29:$A$34,0)),"")="","",IFERROR(INDEX(Constants!$C$29:$C$34,MATCH('Run Matrix (Inputs)'!$G$14,Constants!$A$29:$A$34,0)),"")) -> 717 | G14: =IF(OR($C$14="",$E$14=""),"",(1-'Run Matrix (Inputs)'!$H$14/100)*Constants!$C$22+$B$14*$C$14+$B$14*$E$14) -> 760.914 | H14: =IF(OR(OR($C$14="",$E$14=""),$G$14=""),"",((1-'Run Matrix (Inputs)'!$H$14/100)*Constants!$C$22*Constants!$C$23+$B$14*$C$14*$D$14+$B$14*$E$14*$F$14)/$G$14) -> 1932.6486 | I14: =Constants!$C$24*(1+Constants!$C$16*'Run Matrix (Inputs)'!$H$14/100) -> 0.097719285 | J14: =Constants!$C$25*((1+Constants!$C$17*$B$14+Constants!$C$18*$B$14^2)+(1+Constants!$C$17*$B$14+Constants!$C$18*$B$14^2)) -> 0.0016929297
A15: 13 | B15: ='Run Matrix (Inputs)'!$H$15/100/2 -> 0.0025 | C15: =IF(IFERROR(INDEX(Constants!$B$29:$B$34,MATCH('Run Matrix (Inputs)'!$F$15,Constants!$A$29:$A$34,0)),"")="","",IFERROR(INDEX(Constants!$B$29:$B$34,MATCH('Run Matrix (Inputs)'!$F$15,Constants!$A$29:$A$34,0)),"")) | D15: =IF(IFERROR(INDEX(Constants!$C$29:$C$34,MATCH('Run Matrix (Inputs)'!$F$15,Constants!$A$29:$A$34,0)),"")="","",IFERROR(INDEX(Constants!$C$29:$C$34,MATCH('Run Matrix (Inputs)'!$F$15,Constants!$A$29:$A$34,0)),"")) | E15: =IF(IFERROR(INDEX(Constants!$B$29:$B$34,MATCH('Run Matrix (Inputs)'!$G$15,Constants!$A$29:$A$34,0)),"")="","",IFERROR(INDEX(Constants!$B$29:$B$34,MATCH('Run Matrix (Inputs)'!$G$15,Constants!$A$29:$A$34,0)),"")) | F15: =IF(IFERROR(INDEX(Constants!$C$29:$C$34,MATCH('Run Matrix (Inputs)'!$G$15,Constants!$A$29:$A$34,0)),"")="","",IFERROR(INDEX(Constants!$C$29:$C$34,MATCH('Run Matrix (Inputs)'!$G$15,Constants!$A$29:$A$34,0)),"")) | G15: =IF(OR($C$15="",$E$15=""),"",(1-'Run Matrix (Inputs)'!$H$15/100)*Constants!$C$22+$B$15*$C$15+$B$15*$E$15) | H15: =IF(OR(OR($C$15="",$E$15=""),$G$15=""),"",((1-'Run Matrix (Inputs)'!$H$15/100)*Constants!$C$22*Constants!$C$23+$B$15*$C$15*$D$15+$B$15*$E$15*$F$15)/$G$15) | I15: =Constants!$C$24*(1+Constants!$C$16*'Run Matrix (Inputs)'!$H$15/100) -> 0.097719285 | J15: =Constants!$C$25*((1+Constants!$C$17*$B$15+Constants!$C$18*$B$15^2)+(1+Constants!$C$17*$B$15+Constants!$C$18*$B$15^2)) -> 0.0016929297
A16: 14 | B16: 0.005 | C16: 5180 | D16: 670 | E16: 1800 | F16: 717 | G16: 774.628 | H16: 1904.34 | I16: 0.09934 | J16: 0.0017158
A17: 15 | B17: ='Run Matrix (Inputs)'!$H$17/100/2 -> 0.01 | C17: =IF(IFERROR(INDEX(Constants!$B$29:$B$34,MATCH('Run Matrix (Inputs)'!$F$17,Constants!$A$29:$A$34,0)),"")="","",IFERROR(INDEX(Constants!$B$29:$B$34,MATCH('Run Matrix (Inputs)'!$F$17,Constants!$A$29:$A$34,0)),"")) | D17: =IF(IFERROR(INDEX(Constants!$C$29:$C$34,MATCH('Run Matrix (Inputs)'!$F$17,Constants!$A$29:$A$34,0)),"")="","",IFERROR(INDEX(Constants!$C$29:$C$34,MATCH('Run Matrix (Inputs)'!$F$17,Constants!$A$29:$A$34,0)),"")) | E17: =IF(IFERROR(INDEX(Constants!$B$29:$B$34,MATCH('Run Matrix (Inputs)'!$G$17,Constants!$A$29:$A$34,0)),"")="","",IFERROR(INDEX(Constants!$B$29:$B$34,MATCH('Run Matrix (Inputs)'!$G$17,Constants!$A$29:$A$34,0)),"")) | F17: =IF(IFERROR(INDEX(Constants!$C$29:$C$34,MATCH('Run Matrix (Inputs)'!$G$17,Constants!$A$29:$A$34,0)),"")="","",IFERROR(INDEX(Constants!$C$29:$C$34,MATCH('Run Matrix (Inputs)'!$G$17,Constants!$A$29:$A$34,0)),"")) | G17: =IF(OR($C$17="",$E$17=""),"",(1-'Run Matrix (Inputs)'!$H$17/100)*Constants!$C$22+$B$17*$C$17+$B$17*$E$17) | H17: =IF(OR(OR($C$17="",$E$17=""),$G$17=""),"",((1-'Run Matrix (Inputs)'!$H$17/100)*Constants!$C$22*Constants!$C$23+$B$17*$C$17*$D$17+$B$17*$E$17*$F$17)/$G$17) | I17: =Constants!$C$24*(1+Constants!$C$16*'Run Matrix (Inputs)'!$H$17/100) -> 0.10257714 | J17: =Constants!$C$25*((1+Constants!$C$17*$B$17+Constants!$C$18*$B$17^2)+(1+Constants!$C$17*$B$17+Constants!$C$18*$B$17^2)) -> 0.0017911152
A18: 16 | B18: 0.01 | C18: 5180 | D18: 670 | E18: 1800 | F18: 717 | G18: 802.056 | H18: 1850.62 | I18: 0.102577 | J18: 0.0017911
A19: 17 | B19: ='Run Matrix (Inputs)'!$H$19/100/2 -> 0.0025 | C19: =IF(IFERROR(INDEX(Constants!$B$29:$B$34,MATCH('Run Matrix (Inputs)'!$F$19,Constants!$A$29:$A$34,0)),"")="","",IFERROR(INDEX(Constants!$B$29:$B$34,MATCH('Run Matrix (Inputs)'!$F$19,Constants!$A$29:$A$34,0)),"")) | D19: =IF(IFERROR(INDEX(Constants!$C$29:$C$34,MATCH('Run Matrix (Inputs)'!$F$19,Constants!$A$29:$A$34,0)),"")="","",IFERROR(INDEX(Constants!$C$29:$C$34,MATCH('Run Matrix (Inputs)'!$F$19,Constants!$A$29:$A$34,0)),"")) | E19: =IF(IFERROR(INDEX(Constants!$B$29:$B$34,MATCH('Run Matrix (Inputs)'!$G$19,Constants!$A$29:$A$34,0)),"")="","",IFERROR(INDEX(Constants!$B$29:$B$34,MATCH('Run Matrix (Inputs)'!$G$19,Constants!$A$29:$A$34,0)),"")) | F19: =IF(IFERROR(INDEX(Constants!$C$29:$C$34,MATCH('Run Matrix (Inputs)'!$G$19,Constants!$A$29:$A$34,0)),"")="","",IFERROR(INDEX(Constants!$C$29:$C$34,MATCH('Run Matrix (Inputs)'!$G$19,Constants!$A$29:$A$34,0)),"")) | G19: =IF(OR($C$19="",$E$19=""),"",(1-'Run Matrix (Inputs)'!$H$19/100)*Constants!$C$22+$B$19*$C$19+$B$19*$E$19) | H19: =IF(OR(OR($C$19="",$E$19=""),$G$19=""),"",((1-'Run Matrix (Inputs)'!$H$19/100)*Constants!$C$22*Constants!$C$23+$B$19*$C$19*$D$19+$B$19*$E$19*$F$19)/$G$19) | I19: =Constants!$C$24*(1+Constants!$C$16*'Run Matrix (Inputs)'!$H$19/100) -> 0.097719285 | J19: =Constants!$C$25*((1+Constants!$C$17*$B$19+Constants!$C$18*$B$19^2)+(1+Constants!$C$17*$B$19+Constants!$C$18*$B$19^2)) -> 0.0016929297
A20: 18 | B20: ='Run Matrix (Inputs)'!$H$20/100/2 -> 0.005 | C20: =IF(IFERROR(INDEX(Constants!$B$29:$B$34,MATCH('Run Matrix (Inputs)'!$F$20,Constants!$A$29:$A$34,0)),"")="","",IFERROR(INDEX(Constants!$B$29:$B$34,MATCH('Run Matrix (Inputs)'!$F$20,Constants!$A$29:$A$34,0)),"")) | D20: =IF(IFERROR(INDEX(Constants!$C$29:$C$34,MATCH('Run Matrix (Inputs)'!$F$20,Constants!$A$29:$A$34,0)),"")="","",IFERROR(INDEX(Constants!$C$29:$C$34,MATCH('Run Matrix (Inputs)'!$F$20,Constants!$A$29:$A$34,0)),"")) | E20: =IF(IFERROR(INDEX(Constants!$B$29:$B$34,MATCH('Run Matrix (Inputs)'!$G$20,Constants!$A$29:$A$34,0)),"")="","",IFERROR(INDEX(Constants!$B$29:$B$34,MATCH('Run Matrix (Inputs)'!$G$20,Constants!$A$29:$A$34,0)),"")) | F20: =IF(IFERROR(INDEX(Constants!$C$29:$C$34,MATCH('Run Matrix (Inputs)'!$G$20,Constants!$A$29:$A$34,0)),"")="","",IFERROR(INDEX(Constants!$C$29:$C$34,MATCH('Run Matrix (Inputs)'!$G$20,Constants!$A$29:$A$34,0)),"")) | G20: =IF(OR($C$20="",$E$20=""),"",(1-'Run Matrix (Inputs)'!$H$20/100)*Constants!$C$22+$B$20*$C$20+$B$20*$E$20) | H20: =IF(OR(OR($C$20="",$E$20=""),$G$20=""),"",((1-'Run Matrix (Inputs)'!$H$20/100)*Constants!$C$22*Constants!$C$23+$B$20*$C$20*$D$20+$B$20*$E$20*$F$20)/$G$20) | I20: =Constants!$C$24*(1+Constants!$C$16*'Run Matrix (Inputs)'!$H$20/100) -> 0.09933857 | J20: =Constants!$C$25*((1+Constants!$C$17*$B$20+Constants!$C$18*$B$20^2)+(1+Constants!$C$17*$B$20+Constants!$C$18*$B$20^2)) -> 0.0017157588
A21: 19 | B21: ='Run Matrix (Inputs)'!$H$21/100/2 -> 0.01 | C21: =IF(IFERROR(INDEX(Constants!$B$29:$B$34,MATCH('Run Matrix (Inputs)'!$F$21,Constants!$A$29:$A$34,0)),"")="","",IFERROR(INDEX(Constants!$B$29:$B$34,MATCH('Run Matrix (Inputs)'!$F$21,Constants!$A$29:$A$34,0)),"")) | D21: =IF(IFERROR(INDEX(Constants!$C$29:$C$34,MATCH('Run Matrix (Inputs)'!$F$21,Constants!$A$29:$A$34,0)),"")="","",IFERROR(INDEX(Constants!$C$29:$C$34,MATCH('Run Matrix (Inputs)'!$F$21,Constants!$A$29:$A$34,0)),"")) | E21: =IF(IFERROR(INDEX(Constants!$B$29:$B$34,MATCH('Run Matrix (Inputs)'!$G$21,Constants!$A$29:$A$34,0)),"")="","",IFERROR(INDEX(Constants!$B$29:$B$34,MATCH('Run Matrix (Inputs)'!$G$21,Constants!$A$29:$A$34,0)),"")) | F21: =IF(IFERROR(INDEX(Constants!$C$29:$C$34,MATCH('Run Matrix (Inputs)'!$G$21,Constants!$A$29:$A$34,0)),"")="","",IFERROR(INDEX(Constants!$C$29:$C$34,MATCH('Run Matrix (Inputs)'!$G$21,Constants!$A$29:$A$34,0)),"")) | G21: =IF(OR($C$21="",$E$21=""),"",(1-'Run Matrix (Inputs)'!$H$21/100)*Constants!$C$22+$B$21*$C$21+$B$21*$E$21) | H21: =IF(OR(OR($C$21="",$E$21=""),$G$21=""),"",((1-'Run Matrix (Inputs)'!$H$21/100)*Constants!$C$22*Constants!$C$23+$B$21*$C$21*$D$21+$B$21*$E$21*$F$21)/$G$21) | I21: =Constants!$C$24*(1+Constants!$C$16*'Run Matrix (Inputs)'!$H$21/100) -> 0.10257714 | J21: =Constants!$C$25*((1+Constants!$C$17*$B$21+Constants!$C$18*$B$21^2)+(1+Constants!$C$17*$B$21+Constants!$C$18*$B$21^2)) -> 0.0017911152
A22: 20 | B22: 0.0025 | C22: 5180 | D22: 670 | E22: 1800 | F22: 717 | G22: 760.914 | H22: 1932.65 | I22: 0.09772 | J22: 0.0016929
A23: 21 | B23: ='Run Matrix (Inputs)'!$H$23/100/2 -> 0.005 | C23: =IF(IFERROR(INDEX(Constants!$B$29:$B$34,MATCH('Run Matrix (Inputs)'!$F$23,Constants!$A$29:$A$34,0)),"")="","",IFERROR(INDEX(Constants!$B$29:$B$34,MATCH('Run Matrix (Inputs)'!$F$23,Constants!$A$29:$A$34,0)),"")) | D23: =IF(IFERROR(INDEX(Constants!$C$29:$C$34,MATCH('Run Matrix (Inputs)'!$F$23,Constants!$A$29:$A$34,0)),"")="","",IFERROR(INDEX(Constants!$C$29:$C$34,MATCH('Run Matrix (Inputs)'!$F$23,Constants!$A$29:$A$34,0)),"")) | E23: =IF(IFERROR(INDEX(Constants!$B$29:$B$34,MATCH('Run Matrix (Inputs)'!$G$23,Constants!$A$29:$A$34,0)),"")="","",IFERROR(INDEX(Constants!$B$29:$B$34,MATCH('Run Matrix (Inputs)'!$G$23,Constants!$A$29:$A$34,0)),"")) | F23: =IF(IFERROR(INDEX(Constants!$C$29:$C$34,MATCH('Run Matrix (Inputs)'!$G$23,Constants!$A$29:$A$34,0)),"")="","",IFERROR(INDEX(Constants!$C$29:$C$34,MATCH('Run Matrix (Inputs)'!$G$23,Constants!$A$29:$A$34,0)),"")) | G23: =IF(OR($C$23="",$E$23=""),"",(1-'Run Matrix (Inputs)'!$H$23/100)*Constants!$C$22+$B$23*$C$23+$B$23*$E$23) | H23: =IF(OR(OR($C$23="",$E$23=""),$G$23=""),"",((1-'Run Matrix (Inputs)'!$H$23/100)*Constants!$C$22*Constants!$C$23+$B$23*$C$23*$D$23+$B$23*$E$23*$F$23)/$G$23) | I23: =Constants!$C$24*(1+Constants!$C$16*'Run Matrix (Inputs)'!$H$23/100) -> 0.09933857 | J23: =Constants!$C$25*((1+Constants!$C$17*$B$23+Constants!$C$18*$B$23^2)+(1+Constants!$C$17*$B$23+Constants!$C$18*$B$23^2)) -> 0.0017157588
A24: 22 | B24: 0.005 | C24: 5180 | D24: 670 | E24: 1800 | F24: 717 | G24: 774.628 | H24: 1904.34 | I24: 0.09934 | J24: 0.0017158
A25: 23 | B25: ='Run Matrix (Inputs)'!$H$25/100/2 -> 0.01 | C25: =IF(IFERROR(INDEX(Constants!$B$29:$B$34,MATCH('Run Matrix (Inputs)'!$F$25,Constants!$A$29:$A$34,0)),"")="","",IFERROR(INDEX(Constants!$B$29:$B$34,MATCH('Run Matrix (Inputs)'!$F$25,Constants!$A$29:$A$34,0)),"")) | D25: =IF(IFERROR(INDEX(Constants!$C$29:$C$34,MATCH('Run Matrix (Inputs)'!$F$25,Constants!$A$29:$A$34,0)),"")="","",IFERROR(INDEX(Constants!$C$29:$C$34,MATCH('Run Matrix (Inputs)'!$F$25,Constants!$A$29:$A$34,0)),"")) | E25: =IF(IFERROR(INDEX(Constants!$B$29:$B$34,MATCH('Run Matrix (Inputs)'!$G$25,Constants!$A$29:$A$34,0)),"")="","",IFERROR(INDEX(Constants!$B$29:$B$34,MATCH('Run Matrix (Inputs)'!$G$25,Constants!$A$29:$A$34,0)),"")) | F25: =IF(IFERROR(INDEX(Constants!$C$29:$C$34,MATCH('Run Matrix (Inputs)'!$G$25,Constants!$A$29:$A$34,0)),"")="","",IFERROR(INDEX(Constants!$C$29:$C$34,MATCH('Run Matrix (Inputs)'!$G$25,Constants!$A$29:$A$34,0)),"")) | G25: =IF(OR($C$25="",$E$25=""),"",(1-'Run Matrix (Inputs)'!$H$25/100)*Constants!$C$22+$B$25*$C$25+$B$25*$E$25) | H25: =IF(OR(OR($C$25="",$E$25=""),$G$25=""),"",((1-'Run Matrix (Inputs)'!$H$25/100)*Constants!$C$22*Constants!$C$23+$B$25*$C$25*$D$25+$B$25*$E$25*$F$25)/$G$25) | I25: =Constants!$C$24*(1+Constants!$C$16*'Run Matrix (Inputs)'!$H$25/100) -> 0.10257714 | J25: =Constants!$C$25*((1+Constants!$C$17*$B$25+Constants!$C$18*$B$25^2)+(1+Constants!$C$17*$B$25+Constants!$C$18*$B$25^2)) -> 0.0017911152
A26: 24 | B26: ='Run Matrix (Inputs)'!$H$26/100/2 -> 0.0025 | C26: =IF(IFERROR(INDEX(Constants!$B$29:$B$34,MATCH('Run Matrix (Inputs)'!$F$26,Constants!$A$29:$A$34,0)),"")="","",IFERROR(INDEX(Constants!$B$29:$B$34,MATCH('Run Matrix (Inputs)'!$F$26,Constants!$A$29:$A$34,0)),"")) | D26: =IF(IFERROR(INDEX(Constants!$C$29:$C$34,MATCH('Run Matrix (Inputs)'!$F$26,Constants!$A$29:$A$34,0)),"")="","",IFERROR(INDEX(Constants!$C$29:$C$34,MATCH('Run Matrix (Inputs)'!$F$26,Constants!$A$29:$A$34,0)),"")) | E26: =IF(IFERROR(INDEX(Constants!$B$29:$B$34,MATCH('Run Matrix (Inputs)'!$G$26,Constants!$A$29:$A$34,0)),"")="","",IFERROR(INDEX(Constants!$B$29:$B$34,MATCH('Run Matrix (Inputs)'!$G$26,Constants!$A$29:$A$34,0)),"")) | F26: =IF(IFERROR(INDEX(Constants!$C$29:$C$34,MATCH('Run Matrix (Inputs)'!$G$26,Constants!$A$29:$A$34,0)),"")="","",IFERROR(INDEX(Constants!$C$29:$C$34,MATCH('Run Matrix (Inputs)'!$G$26,Constants!$A$29:$A$34,0)),"")) | G26: =IF(OR($C$26="",$E$26=""),"",(1-'Run Matrix (Inputs)'!$H$26/100)*Constants!$C$22+$B$26*$C$26+$B$26*$E$26) | H26: =IF(OR(OR($C$26="",$E$26=""),$G$26=""),"",((1-'Run Matrix (Inputs)'!$H$26/100)*Constants!$C$22*Constants!$C$23+$B$26*$C$26*$D$26+$B$26*$E$26*$F$26)/$G$26) | I26: =Constants!$C$24*(1+Constants!$C$16*'Run Matrix (Inputs)'!$H$26/100) -> 0.097719285 | J26: =Constants!$C$25*((1+Constants!$C$17*$B$26+Constants!$C$18*$B$26^2)+(1+Constants!$C$17*$B$26+Constants!$C$18*$B$26^2)) -> 0.0016929297
A27: 25 | B27: ='Run Matrix (Inputs)'!$H$27/100/2 -> 0.0025 | C27: =IF(IFERROR(INDEX(Constants!$B$29:$B$34,MATCH('Run Matrix (Inputs)'!$F$27,Constants!$A$29:$A$34,0)),"")="","",IFERROR(INDEX(Constants!$B$29:$B$34,MATCH('Run Matrix (Inputs)'!$F$27,Constants!$A$29:$A$34,0)),"")) | D27: =IF(IFERROR(INDEX(Constants!$C$29:$C$34,MATCH('Run Matrix (Inputs)'!$F$27,Constants!$A$29:$A$34,0)),"")="","",IFERROR(INDEX(Constants!$C$29:$C$34,MATCH('Run Matrix (Inputs)'!$F$27,Constants!$A$29:$A$34,0)),"")) | E27: =IF(IFERROR(INDEX(Constants!$B$29:$B$34,MATCH('Run Matrix (Inputs)'!$G$27,Constants!$A$29:$A$34,0)),"")="","",IFERROR(INDEX(Constants!$B$29:$B$34,MATCH('Run Matrix (Inputs)'!$G$27,Constants!$A$29:$A$34,0)),"")) | F27: =IF(IFERROR(INDEX(Constants!$C$29:$C$34,MATCH('Run Matrix (Inputs)'!$G$27,Constants!$A$29:$A$34,0)),"")="","",IFERROR(INDEX(Constants!$C$29:$C$34,MATCH('Run Matrix (Inputs)'!$G$27,Constants!$A$29:$A$34,0)),"")) | G27: =IF(OR($C$27="",$E$27=""),"",(1-'Run Matrix (Inputs)'!$H$27/100)*Constants!$C$22+$B$27*$C$27+$B$27*$E$27) | H27: =IF(OR(OR($C$27="",$E$27=""),$G$27=""),"",((1-'Run Matrix (Inputs)'!$H$27/100)*Constants!$C$22*Constants!$C$23+$B$27*$C$27*$D$27+$B$27*$E$27*$F$27)/$G$27) | I27: =Constants!$C$24*(1+Constants!$C$16*'Run Matrix (Inputs)'!$H$27/100) -> 0.097719285 | J27: =Constants!$C$25*((1+Constants!$C$17*$B$27+Constants!$C$18*$B$27^2)+(1+Constants!$C$17*$B$27+Constants!$C$18*$B$27^2)) -> 0.0016929297
A28: 26 | B28: ='Run Matrix (Inputs)'!$H$28/100/2 -> 0.005 | C28: =IF(IFERROR(INDEX(Constants!$B$29:$B$34,MATCH('Run Matrix (Inputs)'!$F$28,Constants!$A$29:$A$34,0)),"")="","",IFERROR(INDEX(Constants!$B$29:$B$34,MATCH('Run Matrix (Inputs)'!$F$28,Constants!$A$29:$A$34,0)),"")) | D28: =IF(IFERROR(INDEX(Constants!$C$29:$C$34,MATCH('Run Matrix (Inputs)'!$F$28,Constants!$A$29:$A$34,0)),"")="","",IFERROR(INDEX(Constants!$C$29:$C$34,MATCH('Run Matrix (Inputs)'!$F$28,Constants!$A$29:$A$34,0)),"")) | E28: =IF(IFERROR(INDEX(Constants!$B$29:$B$34,MATCH('Run Matrix (Inputs)'!$G$28,Constants!$A$29:$A$34,0)),"")="","",IFERROR(INDEX(Constants!$B$29:$B$34,MATCH('Run Matrix (Inputs)'!$G$28,Constants!$A$29:$A$34,0)),"")) | F28: =IF(IFERROR(INDEX(Constants!$C$29:$C$34,MATCH('Run Matrix (Inputs)'!$G$28,Constants!$A$29:$A$34,0)),"")="","",IFERROR(INDEX(Constants!$C$29:$C$34,MATCH('Run Matrix (Inputs)'!$G$28,Constants!$A$29:$A$34,0)),"")) | G28: =IF(OR($C$28="",$E$28=""),"",(1-'Run Matrix (Inputs)'!$H$28/100)*Constants!$C$22+$B$28*$C$28+$B$28*$E$28) | H28: =IF(OR(OR($C$28="",$E$28=""),$G$28=""),"",((1-'Run Matrix (Inputs)'!$H$28/100)*Constants!$C$22*Constants!$C$23+$B$28*$C$28*$D$28+$B$28*$E$28*$F$28)/$G$28) | I28: =Constants!$C$24*(1+Constants!$C$16*'Run Matrix (Inputs)'!$H$28/100) -> 0.09933857 | J28: =Constants!$C$25*((1+Constants!$C$17*$B$28+Constants!$C$18*$B$28^2)+(1+Constants!$C$17*$B$28+Constants!$C$18*$B$28^2)) -> 0.0017157588
A29: 27 | B29: 0.01 | C29: 5180 | D29: 670 | E29: 1800 | F29: 717 | G29: 802.056 | H29: 1850.62 | I29: 0.102577 | J29: 0.0017911

Sheet Fluent Raw Results
A1: Run | B1: mdot_in (kg/s) | C1: mdot_out (kg/s) | D1: p_in (Pa) | E1: p_out (Pa) | F1: T_in (K) | G1: T_out (K) | H1: T_wall (K) | I1: tau_w (Pa) | J1: q_flux_avg (W/m2) | K1: Q_dot_total (W) | L1: y+_avg | M1: y+_max | N1: S_gen_total (W/K) | O1: S_gen_H (W/K) | P1: Swirl number
A2: Baseline | B2: 0.41748124 | C2: 0.41747989 | D2: 10.590583 | E2: 0 | F2: 500 | G2: 519.09171 | H2: 660.03433 | I2: 0.07788985 | J2: 35607.497 | K2: 16106.493 | L2: 0.072958528 | M2: 0.61857802
A3: 1 | B3: 0.85275274 | C3: 0.85274808 | D3: 109.25306 | E3: 0 | F3: 500 | G3: 509.3496 | H3: 598.59308 | I3: 0.43263814 | J3: 35606.134 | K3: 15656.949 | L3: 0.07250699 | M3: 0.69737631
A4: 2
A5: 3
A6: 4
A7: 5
A8: 6 | B8: 0.81956674 | C8: 0.81953926 | D8: 212.57862 | E8: 0 | F8: 500 | G8: 510.15269 | H8: 618.87187 | I8: 0.71498517 | J8: 35610.415 | K8: 15659.348 | L8: 0.046114454 | M8: 0.49609798
A9: 7
A10: 8
A11: 9
A12: 10
A13: 11
A14: 12 | B14: 0.85199436 | C14: 0.85202275 | D14: 128.01882 | E14: 0 | F14: 500 | G14: 509.55327 | H14: 636.55458 | I14: 0.55386734 | J14: 35606.134 | K14: 15656.949 | L14: 0.040340282 | M14: 0.49711385
A15: 13
A16: 14
A17: 15
A18: 16
A19: 17
A20: 18
A21: 19
A22: 20
A23: 21
A24: 22
A25: 23
A26: 24
... A29: 27

Sheet Computed Results
A1: Run | B1: A_total (m2) | C1: u_m (m/s) | D1: Re_check | E1: T_b (K) | F1: dP (Pa) | G1: f | H1: h (W/m2K) | I1: Nu | J1: Q_u (W) | K1: P_p (W) | L1: eta_th | M1: eta_ex | N1: PEC | O1: Be | P1: Ns | Q1: Mass balance err (%)
A2: Baseline | B2: =PI()*Constants!$C$4^2/4 -> 0.0034211944 | C2: =IFERROR('Fluent Raw Results'!$B$2/('Fluid Properties'!$G$2*$B$2),"") -> 0.1633136 | D2: =IFERROR('Fluid Properties'!$G$2*$C$2*Constants!$C$4/'Fluid Properties'!$J$2,"") -> 9587.9081 | E2: =IF(OR('Fluent Raw Results'!$F$2="",'Fluent Raw Results'!$G$2=""),"",('Fluent Raw Results'!$F$2+'Fluent Raw Results'!$G$2)/2) -> 509.54586 | F2: =IF(OR('Fluent Raw Results'!$D$2="",'Fluent Raw Results'!$E$2=""),"",'Fluent Raw Results'!$D$2-'Fluent Raw Results'!$E$2) -> 10.590583 | G2: =IFERROR(2*'Fluent Raw Results'!$I$2/('Fluid Properties'!$G$2*$C$2^2),"") -> 0.0078168054 | H2: =IFERROR('Fluent Raw Results'!$J$2/('Fluent Raw Results'!$H$2-$E$2),"") -> 236.61278 | I2: =IFERROR($H$2*Constants!$C$4/'Fluid Properties'!$I$2,"") -> 162.50202 | J2: =IFERROR('Fluent Raw Results'!$B$2*'Fluid Properties'!$H$2*('Fluent Raw Results'!$G$2-'Fluent Raw Results'!$F$2),"") -> 15637.985 | K2: =IFERROR(('Fluent Raw Results'!$B$2/'Fluid Properties'!$G$2)*$F$2,"") -> 0.0059172507 | L2: =IFERROR(($J$2-$K$2/Constants!$C$13)/(Constants!$C$9*Constants!$C$10),"") -> 0.39892769 | M2: =IFERROR('Fluent Raw Results'!$B$2*'Fluid Properties'!$H$2*(('Fluent Raw Results'!$G$2-'Fluent Raw Results'!$F$2)-Constants!$C$11*LN('Fluent Raw Results'!$G$2/'Fluent Raw Results'!$F$2))/(Constants!$C$9*Constants!$C$10*(1+(1/3)*(Constants!$C$11/Constants!$C$12)^4-(4/3)*(Constants!$C$11/Constants!$C$12))),"") -> 0.17617768 | N2: — | O2: =IFERROR('Fluent Raw Results'!$O$2/'Fluent Raw Results'!$N$2,"") | P2: — | Q2: =IFERROR(ABS('Fluent Raw Results'!$B$2-'Fluent Raw Results'!$C$2)/'Fluent Raw Results'!$B$2*100,"") -> 0.00032336782
A3: 1 | B3: =(PI()*Constants!$C$4^2/4-('Run Matrix (Inputs)'!$J$3/1000)^2)+('Run Matrix (Inputs)'!$L$3/1000)^2 -> 0.0033866344 | C3: =IFERROR('Fluent Raw Results'!$B$3/('Fluid Properties'!$G$3*$B$3),"") -> 0.33091712 | D3: =IFERROR('Fluid Properties'!$G$3*$C$3*Constants!$C$4/'Fluid Properties'!$J$3,"") -> 9816.5712 | E3: =IF(OR('Fluent Raw Results'!$F$3="",'Fluent Raw Results'!$G$3=""),"",('Fluent Raw Results'!$F$3+'Fluent Raw Results'!$G$3)/2) -> 504.6748 | F3: =IF(OR('Fluent Raw Results'!$D$3="",'Fluent Raw Results'!$E$3=""),"",'Fluent Raw Results'!$D$3-'Fluent Raw Results'!$E$3) -> 109.25306 | G3: =IFERROR(2*'Fluent Raw Results'!$I$3/('Fluid Properties'!$G$3*$C$3^2),"") -> 0.010384384 | H3: =IFERROR('Fluent Raw Results'!$J$3/('Fluent Raw Results'!$H$3-$E$3),"") -> 379.11825 | I3: =IFERROR($H$3*Constants!$C$4/'Fluid Properties'!$I$3,"") -> 256.058 | J3: =IFERROR('Fluent Raw Results'!$B$3*'Fluid Properties'!$H$3*('Fluent Raw Results'!$G$3-'Fluent Raw Results'!$F$3),"") -> 15408.808 | K3: =IFERROR(('Fluent Raw Results'!$B$3/'Fluid Properties'!$G$3)*$F$3,"") -> 0.12243939 | L3: =IFERROR(($J$3-$K$3/Constants!$C$13)/(Constants!$C$9*Constants!$C$10),"") -> 0.39307143 | M3: =IFERROR('Fluent Raw Results'!$B$3*'Fluid Properties'!$H$3*(('Fluent Raw Results'!$G$3-'Fluent Raw Results'!$F$3)-Constants!$C$11*LN('Fluent Raw Results'!$G$3/'Fluent Raw Results'!$F$3))/(Constants!$C$9*Constants!$C$10*(1+(1/3)*(Constants!$C$11/Constants!$C$12)^4-(4/3)*(Constants!$C$11/Constants!$C$12))),"") -> 0.17121848 | N3: =IFERROR(($I$3/$I$2)/($G$3/$G$2)^(1/3),"") -> 1.4333836 | O3: =IFERROR('Fluent Raw Results'!$O$3/'Fluent Raw Results'!$N$3,"") | P3: =IFERROR('Fluent Raw Results'!$N$3/'Fluent Raw Results'!$N$2,"") | Q3: =IFERROR(ABS('Fluent Raw Results'!$B$3-'Fluent Raw Results'!$C$3)/'Fluent Raw Results'!$B$3*100,"") -> 0.00054646556
A4: 2 | B4: =(PI()*Constants!$C$4^2/4-('Run Matrix (Inputs)'!$J$4/1000)^2)+('Run Matrix (Inputs)'!$L$4/1000)^2 -> 0.0033549544 | C4: =IFERROR('Fluent Raw Results'!$B$4/('Fluid Properties'!$G$4*$B$4),"") | D4: =IFERROR('Fluid Properties'!$G$4*$C$4*Constants!$C$4/'Fluid Properties'!$J$4,"") | E4: =IF(OR('Fluent Raw Results'!$F$4="",'Fluent Raw Results'!$G$4=""),"",('Fluent Raw Results'!$F$4+'Fluent Raw Results'!$G$4)/2) | F4: =IF(OR('Fluent Raw Results'!$D$4="",'Fluent Raw Results'!$E$4=""),"",'Fluent Raw Results'!$D$4-'Fluent Raw Results'!$E$4) | G4: =IFERROR(2*'Fluent Raw Results'!$I$4/('Fluid Properties'!$G$4*$C$4^2),"") | H4: =IFERROR('Fluent Raw Results'!$J$4/('Fluent Raw Results'!$H$4-$E$4),"") | I4: =IFERROR($H$4*Constants!$C$4/'Fluid Properties'!$I$4,"") | J4: =IFERROR('Fluent Raw Results'!$B$4*'Fluid Properties'!$H$4*('Fluent Raw Results'!$G$4-'Fluent Raw Results'!$F$4),"") | K4: =IFERROR(('Fluent Raw Results'!$B$4/'Fluid Properties'!$G$4)*$F$4,"") | L4: =IFERROR(($J$4-$K$4/Constants!$C$13)/(Constants!$C$9*Constants!$C$10),"") | M4: =IFERROR('Fluent Raw Results'!$B$4*'Fluid Properties'!$H$4*(('Fluent Raw Results'!$G$4-'Fluent Raw Results'!$F$4)-Constants!$C$11*LN('Fluent Raw Results'!$G$4/'Fluent Raw Results'!$F$4))/(Constants!$C$9*Constants!$C$10*(1+(1/3)*(Constants!$C$11/Constants!$C$12)^4-(4/3)*(Constants!$C$11/Constants!$C$12))),"") | N4: =IFERROR(($I$4/$I$2)/($G$4/$G$2)^(1/3),"") | O4: =IFERROR('Fluent Raw Results'!$O$4/'Fluent Raw Results'!$N$4,"") | P4: =IFERROR('Fluent Raw Results'!$N$4/'Fluent Raw Results'!$N$2,"") | Q4: =IFERROR(ABS('Fluent Raw Results'!$B$4-'Fluent Raw Results'!$C$4)/'Fluent Raw Results'!$B$4*100,"")
A5: 3 | B5: =(PI()*Constants!$C$4^2/4-('Run Matrix (Inputs)'!$J$5/1000)^2)+('Run Matrix (Inputs)'!$L$5/1000)^2 -> 0.0033261544 | C5: =IFERROR('Fluent Raw Results'!$B$5/('Fluid Properties'!$G$5*$B$5),"") | D5: =IFERROR('Fluid Properties'!$G$5*$C$5*Constants!$C$4/'Fluid Properties'!$J$5,"") | E5: =IF(OR('Fluent Raw Results'!$F$5="",'Fluent Raw Results'!$G$5=""),"",('Fluent Raw Results'!$F$5+'Fluent Raw Results'!$G$5)/2) | F5: =IF(OR('Fluent Raw Results'!$D$5="",'Fluent Raw Results'!$E$5=""),"",'Fluent Raw Results'!$D$5-'Fluent Raw Results'!$E$5) | G5: =IFERROR(2*'Fluent Raw Results'!$I$5/('Fluid Properties'!$G$5*$C$5^2),"") | H5: =IFERROR('Fluent Raw Results'!$J$5/('Fluent Raw Results'!$H$5-$E$5),"") | I5: =IFERROR($H$5*Constants!$C$4/'Fluid Properties'!$I$5,"") | J5: =IFERROR('Fluent Raw Results'!$B$5*'Fluid Properties'!$H$5*('Fluent Raw Results'!$G$5-'Fluent Raw Results'!$F$5),"") | K5: =IFERROR(('Fluent Raw Results'!$B$5/'Fluid Properties'!$G$5)*$F$5,"") | L5: =IFERROR(($J$5-$K$5/Constants!$C$13)/(Constants!$C$9*Constants!$C$10),"") | M5: =IFERROR('Fluent Raw Results'!$B$5*'Fluid Properties'!$H$5*(('Fluent Raw Results'!$G$5-'Fluent Raw Results'!$F$5)-Constants!$C$11*LN('Fluent Raw Results'!$G$5/'Fluent Raw Results'!$F$5))/(Constants!$C$9*Constants!$C$10*(1+(1/3)*(Constants!$C$11/Constants!$C$12)^4-(4/3)*(Constants!$C$11/Constants!$C$12))),"") | N5: =IFERROR(($I$5/$I$2)/($G$5/$G$2)^(1/3),"") | O5: =IFERROR('Fluent Raw Results'!$O$5/'Fluent Raw Results'!$N$5,"") | P5: =IFERROR('Fluent Raw Results'!$N$5/'Fluent Raw Results'!$N$2,"") | Q5: =IFERROR(ABS('Fluent Raw Results'!$B$5-'Fluent Raw Results'!$C$5)/'Fluent Raw Results'!$B$5*100,"")
A6: 4 | B6: =(PI()*Constants!$C$4^2/4-('Run Matrix (Inputs)'!$J$6/1000)^2)+('Run Matrix (Inputs)'!$L$6/1000)^2 -> 0.0033251944 | C6: =IFERROR('Fluent Raw Results'!$B$6/('Fluid Properties'!$G$6*$B$6),"") | D6: =IFERROR('Fluid Properties'!$G$6*$C$6*Constants!$C$4/'Fluid Properties'!$J$6,"") | E6: =IF(OR('Fluent Raw Results'!$F$6="",'Fluent Raw Results'!$G$6=""),"",('Fluent Raw Results'!$F$6+'Fluent Raw Results'!$G$6)/2) | F6: =IF(OR('Fluent Raw Results'!$D$6="",'Fluent Raw Results'!$E$6=""),"",'Fluent Raw Results'!$D$6-'Fluent Raw Results'!$E$6) | G6: =IFERROR(2*'Fluent Raw Results'!$I$6/('Fluid Properties'!$G$6*$C$6^2),"") | H6: =IFERROR('Fluent Raw Results'!$J$6/('Fluent Raw Results'!$H$6-$E$6),"") | I6: =IFERROR($H$6*Constants!$C$4/'Fluid Properties'!$I$6,"") | J6: =IFERROR('Fluent Raw Results'!$B$6*'Fluid Properties'!$H$6*('Fluent Raw Results'!$G$6-'Fluent Raw Results'!$F$6),"") | K6: =IFERROR(('Fluent Raw Results'!$B$6/'Fluid Properties'!$G$6)*$F$6,"") | L6: =IFERROR(($J$6-$K$6/Constants!$C$13)/(Constants!$C$9*Constants!$C$10),"") | M6: =IFERROR('Fluent Raw Results'!$B$6*'Fluid Properties'!$H$6*(('Fluent Raw Results'!$G$6-'Fluent Raw Results'!$F$6)-Constants!$C$11*LN('Fluent Raw Results'!$G$6/'Fluent Raw Results'!$F$6))/(Constants!$C$9*Constants!$C$10*(1+(1/3)*(Constants!$C$11/Constants!$C$12)^4-(4/3)*(Constants!$C$11/Constants!$C$12))),"") | N6: =IFERROR(($I$6/$I$2)/($G$6/$G$2)^(1/3),"") | O6: =IFERROR('Fluent Raw Results'!$O$6/'Fluent Raw Results'!$N$6,"") | P6: =IFERROR('Fluent Raw Results'!$N$6/'Fluent Raw Results'!$N$2,"") | Q6: =IFERROR(ABS('Fluent Raw Results'!$B$6-'Fluent Raw Results'!$C$6)/'Fluent Raw Results'!$B$6*100,"")
A7: 5 | B7: =(PI()*Constants!$C$4^2/4-('Run Matrix (Inputs)'!$J$7/1000)^2)+('Run Matrix (Inputs)'!$L$7/1000)^2 -> 0.0032371944 | C7: =IFERROR('Fluent Raw Results'!$B$7/('Fluid Properties'!$G$7*$B$7),"") | D7: =IFERROR('Fluid Properties'!$G$7*$C$7*Constants!$C$4/'Fluid Properties'!$J$7,"") | E7: =IF(OR('Fluent Raw Results'!$F$7="",'Fluent Raw Results'!$G$7=""),"",('Fluent Raw Results'!$F$7+'Fluent Raw Results'!$G$7)/2) | F7: =IF(OR('Fluent Raw Results'!$D$7="",'Fluent Raw Results'!$E$7=""),"",'Fluent Raw Results'!$D$7-'Fluent Raw Results'!$E$7) | G7: =IFERROR(2*'Fluent Raw Results'!$I$7/('Fluid Properties'!$G$7*$C$7^2),"") | H7: =IFERROR('Fluent Raw Results'!$J$7/('Fluent Raw Results'!$H$7-$E$7),"") | I7: =IFERROR($H$7*Constants!$C$4/'Fluid Properties'!$I$7,"") | J7: =IFERROR('Fluent Raw Results'!$B$7*'Fluid Properties'!$H$7*('Fluent Raw Results'!$G$7-'Fluent Raw Results'!$F$7),"") | K7: =IFERROR(('Fluent Raw Results'!$B$7/'Fluid Properties'!$G$7)*$F$7,"") | L7: =IFERROR(($J$7-$K$7/Constants!$C$13)/(Constants!$C$9*Constants!$C$10),"") | M7: =IFERROR('Fluent Raw Results'!$B$7*'Fluid Properties'!$H$7*(('Fluent Raw Results'!$G$7-'Fluent Raw Results'!$F$7)-Constants!$C$11*LN('Fluent Raw Results'!$G$7/'Fluent Raw Results'!$F$7))/(Constants!$C$9*Constants!$C$10*(1+(1/3)*(Constants!$C$11/Constants!$C$12)^4-(4/3)*(Constants!$C$11/Constants!$C$12))),"") | N7: =IFERROR(($I$7/$I$2)/($G$7/$G$2)^(1/3),"") | O7: =IFERROR('Fluent Raw Results'!$O$7/'Fluent Raw Results'!$N$7,"") | P7: =IFERROR('Fluent Raw Results'!$N$7/'Fluent Raw Results'!$N$2,"") | Q7: =IFERROR(ABS('Fluent Raw Results'!$B$7-'Fluent Raw Results'!$C$7)/'Fluent Raw Results'!$B$7*100,"")
A8: 6 | B8: =(PI()*Constants!$C$4^2/4-('Run Matrix (Inputs)'!$J$8/1000)^2)+('Run Matrix (Inputs)'!$L$8/1000)^2 -> 0.0031571944 | C8: =IFERROR('Fluent Raw Results'!$B$8/('Fluid Properties'!$G$8*$B$8),"") -> 0.33511187 | D8: =IFERROR('Fluid Properties'!$G$8*$C$8*Constants!$C$4/'Fluid Properties'!$J$8,"") -> 9985.5204 | E8: =IF(OR('Fluent Raw Results'!$F$8="",'Fluent Raw Results'!$G$8=""),"",('Fluent Raw Results'!$F$8+'Fluent Raw Results'!$G$8)/2) -> 505.07635 | F8: =IF(OR('Fluent Raw Results'!$D$8="",'Fluent Raw Results'!$E$8=""),"",'Fluent Raw Results'!$D$8-'Fluent Raw Results'!$E$8) -> 212.57862 | G8: =IFERROR(2*'Fluent Raw Results'!$I$8/('Fluid Properties'!$G$8*$C$8^2),"") -> 0.016438198 | H8: =IFERROR('Fluent Raw Results'!$J$8/('Fluent Raw Results'!$H$8-$E$8),"") -> 312.93335 | I8: =IFERROR($H$8*Constants!$C$4/'Fluid Properties'!$I$8,"") -> 207.9112 | J8: =IFERROR('Fluent Raw Results'!$B$8*'Fluid Properties'!$H$8*('Fluent Raw Results'!$G$8-'Fluent Raw Results'!$F$8),"") -> 15845.615 | K8: =IFERROR(('Fluent Raw Results'!$B$8/'Fluid Properties'!$G$8)*$F$8,"") -> 0.22491101 | L8: =IFERROR(($J$8-$K$8/Constants!$C$13)/(Constants!$C$9*Constants!$C$10),"") -> 0.40420574 | M8: =IFERROR('Fluent Raw Results'!$B$8*'Fluid Properties'!$H$8*(('Fluent Raw Results'!$G$8-'Fluent Raw Results'!$F$8)-Constants!$C$11*LN('Fluent Raw Results'!$G$8/'Fluent Raw Results'!$F$8))/(Constants!$C$9*Constants!$C$10*(1+(1/3)*(Constants!$C$11/Constants!$C$12)^4-(4/3)*(Constants!$C$11/Constants!$C$12))),"") -> 0.17627604 | N8: =IFERROR(($I$8/$I$2)/($G$8/$G$2)^(1/3),"") -> 0.99864429 | O8: =IFERROR('Fluent Raw Results'!$O$8/'Fluent Raw Results'!$N$8,"") | P8: =IFERROR('Fluent Raw Results'!$N$8/'Fluent Raw Results'!$N$2,"") | Q8: =IFERROR(ABS('Fluent Raw Results'!$B$8-'Fluent Raw Results'!$C$8)/'Fluent Raw Results'!$B$8*100,"") -> 0.0033529911
A9: 7 | B9: =(PI()*Constants!$C$4^2/4-('Run Matrix (Inputs)'!$J$9/1000)^2)+('Run Matrix (Inputs)'!$L$9/1000)^2 -> 0.0032330344 | C9: =IFERROR('Fluent Raw Results'!$B$9/('Fluid Properties'!$G$9*$B$9),"") | D9: =IFERROR('Fluid Properties'!$G$9*$C$9*Constants!$C$4/'Fluid Properties'!$J$9,"") | E9: =IF(OR('Fluent Raw Results'!$F$9="",'Fluent Raw Results'!$G$9=""),"",('Fluent Raw Results'!$F$9+'Fluent Raw Results'!$G$9)/2) | F9: =IF(OR('Fluent Raw Results'!$D$9="",'Fluent Raw Results'!$E$9=""),"",'Fluent Raw Results'!$D$9-'Fluent Raw Results'!$E$9) | G9: =IFERROR(2*'Fluent Raw Results'!$I$9/('Fluid Properties'!$G$9*$C$9^2),"") | H9: =IFERROR('Fluent Raw Results'!$J$9/('Fluent Raw Results'!$H$9-$E$9),"") | I9: =IFERROR($H$9*Constants!$C$4/'Fluid Properties'!$I$9,"") | J9: =IFERROR('Fluent Raw Results'!$B$9*'Fluid Properties'!$H$9*('Fluent Raw Results'!$G$9-'Fluent Raw Results'!$F$9),"") | K9: =IFERROR(('Fluent Raw Results'!$B$9/'Fluid Properties'!$G$9)*$F$9,"") | L9: =IFERROR(($J$9-$K$9/Constants!$C$13)/(Constants!$C$9*Constants!$C$10),"") | M9: =IFERROR('Fluent Raw Results'!$B$9*'Fluid Properties'!$H$9*(('Fluent Raw Results'!$G$9-'Fluent Raw Results'!$F$9)-Constants!$C$11*LN('Fluent Raw Results'!$G$9/'Fluent Raw Results'!$F$9))/(Constants!$C$9*Constants!$C$10*(1+(1/3)*(Constants!$C$11/Constants!$C$12)^4-(4/3)*(Constants!$C$11/Constants!$C$12))),"") | N9: =IFERROR(($I$9/$I$2)/($G$9/$G$2)^(1/3),"") | O9: =IFERROR('Fluent Raw Results'!$O$9/'Fluent Raw Results'!$N$9,"") | P9: =IFERROR('Fluent Raw Results'!$N$9/'Fluent Raw Results'!$N$2,"") | Q9: =IFERROR(ABS('Fluent Raw Results'!$B$9-'Fluent Raw Results'!$C$9)/'Fluent Raw Results'!$B$9*100,"")
A10: 8 | B10: =(PI()*Constants!$C$4^2/4-('Run Matrix (Inputs)'!$J$10/1000)^2)+('Run Matrix (Inputs)'!$L$10/1000)^2 -> 0.0030605544 | C10: =IFERROR('Fluent Raw Results'!$B$10/('Fluid Properties'!$G$10*$B$10),"") -> 0 | D10: =IFERROR('Fluid Properties'!$G$10*$C$10*Constants!$C$4/'Fluid Properties'!$J$10,"") -> 0 | E10: =IF(OR('Fluent Raw Results'!$F$10="",'Fluent Raw Results'!$G$10=""),"",('Fluent Raw Results'!$F$10+'Fluent Raw Results'!$G$10)/2) | F10: =IF(OR('Fluent Raw Results'!$D$10="",'Fluent Raw Results'!$E$10=""),"",'Fluent Raw Results'!$D$10-'Fluent Raw Results'!$E$10) | G10: =IFERROR(2*'Fluent Raw Results'!$I$10/('Fluid Properties'!$G$10*$C$10^2),"") | H10: =IFERROR('Fluent Raw Results'!$J$10/('Fluent Raw Results'!$H$10-$E$10),"") | I10: =IFERROR($H$10*Constants!$C$4/'Fluid Properties'!$I$10,"") | J10: =IFERROR('Fluent Raw Results'!$B$10*'Fluid Properties'!$H$10*('Fluent Raw Results'!$G$10-'Fluent Raw Results'!$F$10),"") -> 0 | K10: =IFERROR(('Fluent Raw Results'!$B$10/'Fluid Properties'!$G$10)*$F$10,"") | L10: =IFERROR(($J$10-$K$10/Constants!$C$13)/(Constants!$C$9*Constants!$C$10),"") | M10: =IFERROR('Fluent Raw Results'!$B$10*'Fluid Properties'!$H$10*(('Fluent Raw Results'!$G$10-'Fluent Raw Results'!$F$10)-Constants!$C$11*LN('Fluent Raw Results'!$G$10/'Fluent Raw Results'!$F$10))/(Constants!$C$9*Constants!$C$10*(1+(1/3)*(Constants!$C$11/Constants!$C$12)^4-(4/3)*(Constants!$C$11/Constants!$C$12))),"") | N10: =IFERROR(($I$10/$I$2)/($G$10/$G$2)^(1/3),"") | O10: =IFERROR('Fluent Raw Results'!$O$10/'Fluent Raw Results'!$N$10,"") | P10: =IFERROR('Fluent Raw Results'!$N$10/'Fluent Raw Results'!$N$2,"") | Q10: =IFERROR(ABS('Fluent Raw Results'!$B$10-'Fluent Raw Results'!$C$10)/'Fluent Raw Results'!$B$10*100,"")
A11: 9 | B11: =(PI()*Constants!$C$4^2/4-('Run Matrix (Inputs)'!$J$11/1000)^2)+('Run Matrix (Inputs)'!$L$11/1000)^2 -> 0.0029037544 | C11: =IFERROR('Fluent Raw Results'!$B$11/('Fluid Properties'!$G$11*$B$11),"") | D11: =IFERROR('Fluid Properties'!$G$11*$C$11*Constants!$C$4/'Fluid Properties'!$J$11,"") | E11: =IF(OR('Fluent Raw Results'!$F$11="",'Fluent Raw Results'!$G$11=""),"",('Fluent Raw Results'!$F$11+'Fluent Raw Results'!$G$11)/2) | F11: =IF(OR('Fluent Raw Results'!$D$11="",'Fluent Raw Results'!$E$11=""),"",'Fluent Raw Results'!$D$11-'Fluent Raw Results'!$E$11) | G11: =IFERROR(2*'Fluent Raw Results'!$I$11/('Fluid Properties'!$G$11*$C$11^2),"") | H11: =IFERROR('Fluent Raw Results'!$J$11/('Fluent Raw Results'!$H$11-$E$11),"") | I11: =IFERROR($H$11*Constants!$C$4/'Fluid Properties'!$I$11,"") | J11: =IFERROR('Fluent Raw Results'!$B$11*'Fluid Properties'!$H$11*('Fluent Raw Results'!$G$11-'Fluent Raw Results'!$F$11),"") | K11: =IFERROR(('Fluent Raw Results'!$B$11/'Fluid Properties'!$G$11)*$F$11,"") | L11: =IFERROR(($J$11-$K$11/Constants!$C$13)/(Constants!$C$9*Constants!$C$10),"") | M11: =IFERROR('Fluent Raw Results'!$B$11*'Fluid Properties'!$H$11*(('Fluent Raw Results'!$G$11-'Fluent Raw Results'!$F$11)-Constants!$C$11*LN('Fluent Raw Results'!$G$11/'Fluent Raw Results'!$F$11))/(Constants!$C$9*Constants!$C$10*(1+(1/3)*(Constants!$C$11/Constants!$C$12)^4-(4/3)*(Constants!$C$11/Constants!$C$12))),"") | N11: =IFERROR(($I$11/$I$2)/($G$11/$G$2)^(1/3),"") | O11: =IFERROR('Fluent Raw Results'!$O$11/'Fluent Raw Results'!$N$11,"") | P11: =IFERROR('Fluent Raw Results'!$N$11/'Fluent Raw Results'!$N$2,"") | Q11: =IFERROR(ABS('Fluent Raw Results'!$B$11-'Fluent Raw Results'!$C$11)/'Fluent Raw Results'!$B$11*100,"")
A12: 10 | B12: =(PI()*Constants!$C$4^2/4-('Run Matrix (Inputs)'!$J$12/1000)^2)+('Run Matrix (Inputs)'!$L$12/1000)^2 -> 0.0033866344 | C12: =IFERROR('Fluent Raw Results'!$B$12/('Fluid Properties'!$G$12*$B$12),"") | D12: =IFERROR('Fluid Properties'!$G$12*$C$12*Constants!$C$4/'Fluid Properties'!$J$12,"") | E12: =IF(OR('Fluent Raw Results'!$F$12="",'Fluent Raw Results'!$G$12=""),"",('Fluent Raw Results'!$F$12+'Fluent Raw Results'!$G$12)/2) | F12: =IF(OR('Fluent Raw Results'!$D$12="",'Fluent Raw Results'!$E$12=""),"",'Fluent Raw Results'!$D$12-'Fluent Raw Results'!$E$12) | G12: =IFERROR(2*'Fluent Raw Results'!$I$12/('Fluid Properties'!$G$12*$C$12^2),"") | H12: =IFERROR('Fluent Raw Results'!$J$12/('Fluent Raw Results'!$H$12-$E$12),"") | I12: =IFERROR($H$12*Constants!$C$4/'Fluid Properties'!$I$12,"") | J12: =IFERROR('Fluent Raw Results'!$B$12*'Fluid Properties'!$H$12*('Fluent Raw Results'!$G$12-'Fluent Raw Results'!$F$12),"") | K12: =IFERROR(('Fluent Raw Results'!$B$12/'Fluid Properties'!$G$12)*$F$12,"") | L12: =IFERROR(($J$12-$K$12/Constants!$C$13)/(Constants!$C$9*Constants!$C$10),"") | M12: =IFERROR('Fluent Raw Results'!$B$12*'Fluid Properties'!$H$12*(('Fluent Raw Results'!$G$12-'Fluent Raw Results'!$F$12)-Constants!$C$11*LN('Fluent Raw Results'!$G$12/'Fluent Raw Results'!$F$12))/(Constants!$C$9*Constants!$C$10*(1+(1/3)*(Constants!$C$11/Constants!$C$12)^4-(4/3)*(Constants!$C$11/Constants!$C$12))),"") | N12: =IFERROR(($I$12/$I$2)/($G$12/$G$2)^(1/3),"") | O12: =IFERROR('Fluent Raw Results'!$O$12/'Fluent Raw Results'!$N$12,"") | P12: =IFERROR('Fluent Raw Results'!$N$12/'Fluent Raw Results'!$N$2,"") | Q12: =IFERROR(ABS('Fluent Raw Results'!$B$12-'Fluent Raw Results'!$C$12)/'Fluent Raw Results'!$B$12*100,"")
