Workbook

Sheet README
A1: Baseline (Smooth Tube) Mesh Independence Study — Full Record
A3: Purpose
A4: Establish mesh independence for the smooth-tube baseline case, using the same generic worst-case convention as the enhanced (promoter) geometry's GCI study, so the two mesh-independence studies are methodologically comparable.
A6: Geometry | B6: Smooth circular tube, no promoter — dti=66mm, dto=70mm, wall=2mm, L=2m
A7: Domain type | B7: Conjugate (2-body): fluid + solid tube, coupled interface
A8: Mesh type | B8: Unstructured tetrahedral (Patch Conforming) with inflation layers — same method as enhanced geometry
A9: Convention matched to | B9: Enhanced-geometry GCI study (mesh-validation/gci_mesh_plan.md) — same Re, Tin, heat flux type, monitors, threshold
A10: Test conditions | B10: Re=100,000 (highest/worst-case Re in operating range), Tin=300K, uniform q"=1000 W/m² — NOT production conditions
A11: Monitors | B11: Nu and ΔP (matching Mohammed et al. 2022's own simple consecutive-mesh-level method)
A12: Threshold | B12: 2% difference between the two finest mesh levels
A13: Note on production Baseline run | B13: A separate real production Baseline run (Re=10,000, Tin=500K, real MCRT UDF heat flux, real Syltherm 800 polynomial properties) was completed 2026-08-19 on this same Mesh 1 geometry/mesh — its data is recorded separately in the 'Production Baseline Run' sheet for later use, once mesh independence is formally established.
A15: Related files
A16: thesis/mesh-validation/gci_mesh_plan.md — enhanced-geometry GCI study + this baseline study's plan
A17: thesis/reference-data/solver_and_formulas.md — governing equations, property models, heat flux profile
A18: thesis/mesh-validation/PTSC_GCI_Workbook.xlsx — enhanced-geometry mesh independence data (for comparison)
A19: thesis/production-runs/PTSC_27Run_Master_Workbook.xlsx — 27-run production tracking
A21: Status (2026-08-19)
A22: Mesh 4 PROVISIONALLY ADOPTED. Mesh 3->4: Nu PASS (0.75%), dP FAIL (2.57%, just above 2%). Mesh 5 in progress to confirm. Production work (Baseline run + Run 2+) proceeding on Mesh 4 in the meantime; will revisit only if Mesh 5 shows a material further change.

Sheet Geometry & Mesh Settings
A1: Geometry & Mesh Settings
A3: Geometry
A4: Tube inner diameter, dti | B4: 66 | C4: mm
A5: Tube outer diameter, dto | B5: 70 | C5: mm
A6: Wall thickness | B6: 2 | C6: mm
A7: Length, L | B7: 2 | C7: m
A8: Domain | B8: Fluid (full bore) + Solid (2mm annular tube wall), shared topology, 1 Part / 2 Bodies
A10: Global Mesh Settings
A11: Physics Preference | B11: CFD
A12: Solver Preference | B12: Fluent
A13: Element Size — Mesh 1 (Coarsest) | B13: 5.0 mm
A14: Element Size — Mesh 2 | B14: 3.85 mm (planned)
A15: Element Size — Mesh 3 | B15: 2.96 mm (planned)
A16: Element Size — Mesh 4 (Finest) | B16: 2.28 mm (planned, if needed)
A17: Use Adaptive Sizing | B17: No
A18: Capture Curvature | B18: Yes
A19: Curvature Normal Angle | B19: 18°
A20: Smoothing | B20: High
A21: Transition | B21: Slow
A22: Method | B22: Tetrahedrons, Patch Conforming Algorithm
A24: Inflation Settings
A25: Scope | B25: Fluid body, boundary = inner_wall (fluid-solid interface)
A26: Inflation Option | B26: First Layer Thickness
A27: First Layer Height | B27: 0.006959 mm
A28: Maximum Layers | B28: 15
A29: Growth Rate | B29: 1.2
A30: Inflation Algorithm | B30: Post

Sheet Material Properties
A1: Material Properties
A3: Solid — Steel (tube wall)
A4: Density | B4: 8030 | C4: kg/m³ | D4: Fluent database default
A5: Specific Heat, Cp | B5: 502.48 | C5: J/kg·K | D5: Fluent database default
A6: Thermal Conductivity, k | B6: 25 | C6: W/m·K | D6: CORRECTED to match Mohammed et al. (2022)'s own stated tube value: "stainless steel (321H) with a thermal conductivity of 25 W/m·K" — Fluent's generic steel database default (16.27) was wrong.
A8: Fluid — Syltherm 800 (used for THIS mesh-independence test)
A9: Constant properties — matches the enhanced-geometry mesh test's own convention exactly (that study predates the discovery of the real T-dependent polynomial below). Used for Mesh 1-4 of this baseline study, NOT for the real production Baseline run.
A11: Property | B11: Value | C11: Unit | D11: Source
A12: Density, ρ | B12: 747.2 | C12: kg/m³ | D12: Table 6, Mohammed et al. (2022) — also = polynomial evaluated at 500K
A13: Viscosity, μ | B13: 0.00084 | C13: Pa·s | D13: Table 6, Mohammed et al. (2022)
A14: Thermal Conductivity, k | B14: 0.0961 | C14: W/m·K | D14: Table 6, Mohammed et al. (2022)
A15: Specific Heat, Cp | B15: 1962 | C15: J/kg·K | D15: Table 6, Mohammed et al. (2022)
A18: Fluid — Syltherm 800 REAL TEMPERATURE-DEPENDENT POLYNOMIAL (reference — used in the separate real production Baseline run, not in this mesh test)
A19: Read directly from Table 5 of the real Mohammed et al. (2022) paper (their ref [66], a Dow Syltherm-800 datasheet fit). Form: ψ = a + bT + cT² + dT³ + eT⁴, T in Kelvin. Verified self-consistent: evaluating at T=500K reproduces Table 6's constants above closely. Valid range demonstrated by the paper's own use: 400–650 K — do not extrapolate far outside this (the actual production Baseline run's T_wall reached ~654K, just past this bound — flagged as a documented minor extrapolation, not a blocker).
A21: Property | B21: Unit | C21: a (C0) | D21: b (C1) | E21: c (C2) | F21: d (C3) | G21: e (C4)
A22: Density | B22: kg/m³ | C22: 1105.7 | D22: -0.41535 | E22: -0.00060616
A23: Viscosity | B23: Pa·s | C23: 0.084866 | D23: -0.00055412 | E23: 1.3882e-06 | F23: -1.566e-09 | G23: 6.672e-13
A24: Thermal Conductivity | B24: W/m·K | C24: 0.19002 | D24: -0.00018752 | E24: -5.7534e-10
A25: Specific Heat, Cp | B25: J/kg·K | C25: 1107.8 | D25: 1.708

Sheet BCs & Solver Settings
A1: Boundary Conditions & Solver Settings — Mesh-Independence Test Convention
A3: Inlet (velocity-inlet)
A4: Velocity Magnitude, u_m | B4: 1.70 | C4: m/s | D4: Re·μ/(ρ·d_ri) = 100,000×0.00084/(747.2×0.066)
A5: Temperature, Tin | B5: 300 | C5: K | D5: Generic mesh-test condition (NOT production 500K)
A6: Turbulence Specification | B6: Intensity and Hydraulic Diameter
A7: Turbulent Intensity | B7: 5 | C7: %
A8: Hydraulic Diameter | B8: 0.066 | C8: m | D8: Full bore diameter (smooth tube — no annulus/core split)
A9: Resulting Re (check) | B9: ≈ 99,800 | D9: Matches enhanced-geometry Coarse level's own logged Re≈99,600
A11: Outlet (pressure-outlet)
A12: Gauge Pressure | B12: 0 | C12: Pa
A14: Wall: outer_wall (solid exterior, sun-facing)
A15: Thermal Condition | B15: Heat Flux
A16: Heat Flux | B16: 1000 (uniform, constant) — NOT the real MCRT UDF used for production runs
A17: Material | B17: steel
A19: Wall: inner_wall / inner_wall-shadow (fluid-solid coupled interface)
A20: Thermal Condition | B20: Coupled
A21: Note | B21: MUST be Coupled, not Heat Flux — an early setup error set this to Heat Flux=0 (i.e. fully insulating), which blocked all heat from crossing into the fluid and caused solid-zone temperature runaway. Caught and fixed before this data was recorded.
A23: Wall: wall-tube (solid end caps)
A24: Thermal Condition | B24: Default (adiabatic) — no BC applied, negligible area
A26: Cell Zones
A27: Fluid zone | B27: syltherm800_oil
A28: Solid zone (tube) | B28: steel
A30: Solver / Models
A31: Solver Type | B31: Pressure-Based, Steady
A32: Viscous Model | B32: Realizable k-epsilon (2 eqn)
A33: Near-Wall Treatment | B33: Enhanced Wall Treatment
A34: Pressure-Velocity Coupling | B34: SIMPLE
A35: Pressure Discretization | B35: PRESTO!
A36: Momentum Discretization | B36: Second Order Upwind
A37: Turbulent KE / Turbulent Dissipation Rate | B37: Second Order Upwind (both)
A38: Energy Discretization | B38: Second Order Upwind
A39: Pseudo Time Method | B39: Local Time Step (stabilizes localized heat-flux stiffness)
A41: Residual Convergence Criteria (Absolute)
A42: Continuity | B42: 1e-06
A43: x/y/z-velocity | B43: 1e-08 each
A44: Energy | B44: 1e-08
A45: k, epsilon | B45: 1e-08 each
A47: Solution Limits
A48: Minimum Static Temperature | B48: 250 K
A49: Maximum Static Temperature | B49: 700 K
...

Sheet Mesh Quality Log
A1: Mesh Quality Log — Baseline Smooth Tube
A3: Level | B3: Element Size (mm) | C3: Elements | D3: Nodes | E3: Max Skewness | F3: Min Orthogonal Quality | G3: Notes
A4: Mesh 1 (Coarsest) | B4: 5 | C4: 1023406 | D4: 385377 | E4: 0.84354 | F4: 0.15646 | G4: Final corrected geometry (fluid body rebuilt via direct Extrude + Form New Part after Fill degenerated to a surface body). Supersedes two earlier invalid attempts (724,846 elements — pre-topology-fix; 1,009,884 elements — earlier regeneration pass).
A5: Mesh 2 | B5: 3.85 | C5: 1762070 | D5: 650727 | E5: 0.84496 | F5: 0.15504 | G5: Recorded 2026-08-19, same convention as Mesh 1 (Re=100,000, Tin=300K, uniform q"=1000 W/m2)
A6: Mesh 3 | B6: 2.96 | C6: 3093142 | D6: 1117290 | E6: 0.84995 | F6: 0.15005 | G6: Recorded 2026-08-19, same convention as Mesh 1/2
A7: Mesh 4 (Finest) | B7: 2.28 | C7: 5825667 | D7: 1986806 | E7: 0.79995 | F7: 0.20005 | G7: Recorded 2026-08-19, same convention as Mesh 1/2/3
A8: Mesh 5 (extra level, ΔP not yet converged at Mesh 4) | B8: 1.75
A9: Quality targets: Min Orthogonal Quality > 0.01 (flag if lower); Max Skewness < 0.95

Sheet Fluent Raw Results
A1: Fluent Raw Results — Mesh-Independence Test Runs (Re=100,000, Tin=300K, uniform q"=1000 W/m²)
A3: Level | B3: Q_dot_total (W) | C3: mdot_in (kg/s) | D3: mdot_out (kg/s) | E3: p_in (Pa) | F3: p_out (Pa) | G3: T_in (K) | H3: T_out (K) | I3: T_wall (K) | J3: tau_w (Pa) | K3: wall_heat_flux_avg (W/m²) | L3: y+ avg | M3: y+ max | N3: Mass balance error (%)
A4: Mesh 1 | B4: 452.16611 | C4: 4.3287479 | D4: -4.3287474 | E4: 670.90516 | F4: 0 | G4: 300 | H4: 300.05324 | I4: 300.86659 | J4: 5.9079351 | K4: 1000 | L4: 0.26817709 | M4: 2.1277173 | N4: 1.2e-05
A5: Mesh 2 | B5: 452.23211 | C5: 4.3359388 | D5: -4.3359386 | E5: 640.89111 | F5: 0 | G5: 300 | H5: 300.05315 | I5: 300.86581 | J5: 6.0110973 | K5: 1000 | L5: 0.27043937 | M5: 2.1768591 | N5: 5e-06
A6: Mesh 3 | B6: 452.29636 | C6: 4.3399049 | D6: -4.3399046 | E6: 598.08387 | F6: 0 | G6: 300 | H6: 300.05311 | I6: 300.85761 | J6: 5.9357157 | K6: 1000 | L6: 0.27342043 | M6: 1.4947357 | N6: 7e-06
A7: Mesh 4 | B7: 452.33431 | C7: 4.3422859 | D7: -4.3422856 | E7: 583.10926 | F7: 0 | G7: 300 | H7: 300.05309 | I7: 300.86379 | J7: 6.0018683 | K7: 1000 | L7: 0.27537764 | M7: 1.5131235 | N7: 7e-06
A8: Mesh 5

Sheet Computed Results
A1: Computed / Derived Results — formulas per solver_and_formulas.md
A3: Constants used
A4: d_ri (tube inner diameter) | B4: 0.066 | C4: m
A5: A_total (full bore area) | B5: =PI()*B4^2/4 | C5: m²
A6: L (length) | B6: 2 | C6: m
A7: rho (constant) | B7: 747.2 | C7: kg/m³
A8: mu (constant) | B8: 0.00084 | C8: Pa·s
A9: k_f (constant) | B9: 0.0961 | C9: W/m·K
A10: Cp (constant) | B10: 1962 | C10: J/kg·K
A12: Level | B12: u_m (m/s) | C12: Re (check) | D12: T_b = (Tin+Tout)/2 (K) | E12: h = q"/(T_wall-T_b) (W/m²K) | F12: Nu = h*d_ri/k_f | G12: f = 2*tau_w/(rho*u_m^2) | H12: dP formula check (4f·L/d·ρu²/2) (Pa) | I12: dP actual (p_in-p_out) (Pa) | J12: dP %diff | K12: Mass balance err (%)
A13: Mesh 1 | B13: =IF('Fluent Raw Results'!C4="","",'Fluent Raw Results'!C4/($B$7*$B$5)) | C13: =IF('Fluent Raw Results'!C4="","",$B$7*B13*$B$4/$B$8) | D13: =IF('Fluent Raw Results'!G4="","",('Fluent Raw Results'!G4+'Fluent Raw Results'!H4)/2) | E13: =IF(OR('Fluent Raw Results'!I4="",D13=""),"",'Fluent Raw Results'!K4/('Fluent Raw Results'!I4-D13)) | F13: =IF(E13="","",E13*$B$4/$B$9) | G13: =IF(OR('Fluent Raw Results'!J4="",B13=""),"",2*'Fluent Raw Results'!J4/($B$7*B13^2)) | H13: =IF(G13="","",4*G13*($B$6/$B$4)*($B$7*B13^2/2)) | I13: =IF('Fluent Raw Results'!E4="","",'Fluent Raw Results'!E4-'Fluent Raw Results'!F4) | J13: =IF(OR(H13="",I13=""),"",ABS(H13-I13)/I13*100) | K13: =IF('Fluent Raw Results'!N4="","",'Fluent Raw Results'!N4)
A14: Mesh 2 | B14: =IF('Fluent Raw Results'!C5="","",'Fluent Raw Results'!C5/($B$7*$B$5)) | C14: =IF('Fluent Raw Results'!C5="","",$B$7*B14*$B$4/$B$8) | D14: =IF('Fluent Raw Results'!G5="","",('Fluent Raw Results'!G5+'Fluent Raw Results'!H5)/2) | E14: =IF(OR('Fluent Raw Results'!I5="",D14=""),"",'Fluent Raw Results'!K5/('Fluent Raw Results'!I5-D14)) | F14: =IF(E14="","",E14*$B$4/$B$9) | G14: =IF(OR('Fluent Raw Results'!J5="",B14=""),"",2*'Fluent Raw Results'!J5/($B$7*B14^2)) | H14: =IF(G14="","",4*G14*($B$6/$B$4)*($B$7*B14^2/2)) | I14: =IF('Fluent Raw Results'!E5="","",'Fluent Raw Results'!E5-'Fluent Raw Results'!F5) | J14: =IF(OR(H14="",I14=""),"",ABS(H14-I14)/I14*100) | K14: =IF('Fluent Raw Results'!N5="","",'Fluent Raw Results'!N5)
A15: Mesh 3 | B15: =IF('Fluent Raw Results'!C6="","",'Fluent Raw Results'!C6/($B$7*$B$5)) | C15: =IF('Fluent Raw Results'!C6="","",$B$7*B15*$B$4/$B$8) | D15: =IF('Fluent Raw Results'!G6="","",('Fluent Raw Results'!G6+'Fluent Raw Results'!H6)/2) | E15: =IF(OR('Fluent Raw Results'!I6="",D15=""),"",'Fluent Raw Results'!K6/('Fluent Raw Results'!I6-D15)) | F15: =IF(E15="","",E15*$B$4/$B$9) | G15: =IF(OR('Fluent Raw Results'!J6="",B15=""),"",2*'Fluent Raw Results'!J6/($B$7*B15^2)) | H15: =IF(G15="","",4*G15*($B$6/$B$4)*($B$7*B15^2/2)) | I15: =IF('Fluent Raw Results'!E6="","",'Fluent Raw Results'!E6-'Fluent Raw Results'!F6) | J15: =IF(OR(H15="",I15=""),"",ABS(H15-I15)/I15*100) | K15: =IF('Fluent Raw Results'!N6="","",'Fluent Raw Results'!N6)
A16: Mesh 4 | B16: =IF('Fluent Raw Results'!C7="","",'Fluent Raw Results'!C7/($B$7*$B$5)) | C16: =IF('Fluent Raw Results'!C7="","",$B$7*B16*$B$4/$B$8) | D16: =IF('Fluent Raw Results'!G7="","",('Fluent Raw Results'!G7+'Fluent Raw Results'!H7)/2) | E16: =IF(OR('Fluent Raw Results'!I7="",D16=""),"",'Fluent Raw Results'!K7/('Fluent Raw Results'!I7-D16)) | F16: =IF(E16="","",E16*$B$4/$B$9) | G16: =IF(OR('Fluent Raw Results'!J7="",B16=""),"",2*'Fluent Raw Results'!J7/($B$7*B16^2)) | H16: =IF(G16="","",4*G16*($B$6/$B$4)*($B$7*B16^2/2)) | I16: =IF('Fluent Raw Results'!E7="","",'Fluent Raw Results'!E7-'Fluent Raw Results'!F7) | J16: =IF(OR(H16="",I16=""),"",ABS(H16-I16)/I16*100) | K16: =IF('Fluent Raw Results'!N7="","",'Fluent Raw Results'!N7)
A17: Mesh 5 | B17: =IF('Fluent Raw Results'!C8="","",'Fluent Raw Results'!C8/($B$7*$B$5)) | C17: =IF('Fluent Raw Results'!C8="","",$B$7*B17*$B$4/$B$8) | D17: =IF('Fluent Raw Results'!G8="","",('Fluent Raw Results'!G8+'Fluent Raw Results'!H8)/2) | E17: =IF(OR('Fluent Raw Results'!I8="",D17=""),"",'Fluent Raw Results'!K8/('Fluent Raw Results'!I8-D17)) | F17: =IF(E17="","",E17*$B$4/$B$9) | G17: =IF(OR('Fluent Raw Results'!J8="",B17=""),"",2*'Fluent Raw Results'!J8/($B$7*B17^2)) | H17: =IF(G17="","",4*G17*($B$6/$B$4)*($B$7*B17^2/2)) | I17: =IF('Fluent Raw Results'!E8="","",'Fluent Raw Results'!E8-'Fluent Raw Results'!F8) | J17: =IF(OR(H17="",I17=""),"",ABS(H17-I17)/I17*100) | K17: =IF('Fluent Raw Results'!N8="","",'Fluent Raw Results'!N8)
A18: Note: the ΔP formula check uses ΔP=4f·(L/d)·(ρu²/2), the Darcy-Weisbach form consistent with f being the Fanning friction factor (f=2τw/ρu²) as defined in solver_and_formulas.md. A small (~5-7%) gap vs. the directly-measured ΔP is expected and has been seen consistently across this project's other runs — flagged as a known minor formula-convention item, not a data error.

Sheet Mesh Independence Check
A1: Mesh Independence Check — simple consecutive-level % method (Mohammed et al. 2022 practice)
A3: Compares the two FINEST mesh levels only. Threshold: 2%. Monitors: Nu, ΔP (actual, measured).
A5: Comparison | B5: Nu (coarser) | C5: Nu (finer) | D5: Nu %diff | E5: dP (coarser) | F5: dP (finer) | G5: dP %diff | H5: Verdict
A6: Mesh 1 -> Mesh 2 | B6: ='Computed Results'!F13 | C6: ='Computed Results'!F14 | D6: =IF(OR(B6="",C6=""),"",ABS(C6-B6)/C6*100) | E6: ='Computed Results'!I13 | F6: ='Computed Results'!I14 | G6: =IF(OR(E6="",F6=""),"",ABS(F6-E6)/F6*100) | H6: =IF(OR(D6="",G6=""),"pending",IF(AND(D6<2,G6<2),"PASS","FAIL — needs finer mesh"))
A7: Mesh 2 -> Mesh 3 | B7: ='Computed Results'!F14 | C7: ='Computed Results'!F15 | D7: =IF(OR(B7="",C7=""),"",ABS(C7-B7)/C7*100) | E7: ='Computed Results'!I14 | F7: ='Computed Results'!I15 | G7: =IF(OR(E7="",F7=""),"",ABS(F7-E7)/F7*100) | H7: =IF(OR(D7="",G7=""),"pending",IF(AND(D7<2,G7<2),"PASS","FAIL — needs finer mesh"))
A8: Mesh 3 -> Mesh 4 | B8: ='Computed Results'!F15 | C8: ='Computed Results'!F16 | D8: =IF(OR(B8="",C8=""),"",ABS(C8-B8)/C8*100) | E8: ='Computed Results'!I15 | F8: ='Computed Results'!I16 | G8: =IF(OR(E8="",F8=""),"",ABS(F8-E8)/F8*100) | H8: =IF(OR(D8="",G8=""),"pending",IF(AND(D8<2,G8<2),"PASS","FAIL — needs finer mesh"))
A9: Mesh 4 -> Mesh 5 | B9: ='Computed Results'!F16 | C9: ='Computed Results'!F17 | D9: =IF(OR(B9="",C9=""),"",ABS(C9-B9)/C9*100) | E9: ='Computed Results'!I16 | F9: ='Computed Results'!I17 | G9: =IF(OR(E9="",F9=""),"",ABS(F9-E9)/F9*100) | H9: =IF(OR(D9="",G9=""),"pending",IF(AND(D9<2,G9<2),"PASS","FAIL — needs finer mesh"))

Sheet Production Baseline Run
A1: Production Baseline Run — Real Conditions (kept separate from the mesh-independence test)
A3: SUPERSEDED: this data was run on Mesh 1 geometry, before mesh independence was checked. Now that Mesh 4 is (provisionally) adopted, this run must be redone on Mesh 4 before use in the 27-run master workbook. Kept below for reference only.
A5: Conditions
A6: Re | B6: 10000
A7: Tin | B7: 500 K
A8: Heat flux | B8: Real MCRT UDF (mohammed_flux_profile) — non-uniform, Table 3 of Mohammed et al. (2022)
A9: Fluid properties | B9: Real temperature-dependent polynomial (Table 5, Mohammed et al. 2022)
A10: Solid material | B10: Steel, k=25 W/m·K
A11: u_m (inlet velocity) | B11: 0.1636 m/s
A13: Raw Fluent Results
A14: Q_dot_total (W) | B14: mdot_in (kg/s) | C14: mdot_out (kg/s) | D14: p_in (Pa) | E14: p_out (Pa) | F14: T_in (K) | G14: T_out (K) | H14: T_wall (K) | I14: tau_w (Pa) | J14: wall_heat_flux_avg (W/m²) | K14: y+ avg | L14: y+ max
A15: 16101.78 | B15: 0.41617966 | C15: -0.41617609 | D15: 13.87821 | E15: 0 | F15: 500 | G15: 519.27201 | H15: 654.29579 | I15: 0.10602777 | J15: 35610.321 | K15: 0.075709744 | L15: 0.77119762
A17: Sanity checks
A18: Mass balance error | B18: 0.000858 % | C18: Excellent — essentially perfect
A19: Energy balance (dT expected vs observed) | B19: ~19.6-19.7K expected (Q/(mdot*Cp)) vs 19.27K observed | C19: Within ~2%, consistent
A20: T_wall vs polynomial valid range (400-650K) | B20: 654.3K — ~4K past the paper's demonstrated upper bound | C20: Minor extrapolation, documented, not a blocker
