Workbook

Sheet ReadMe
B2: PTSC-HTSP Thesis — Meshing & Validation Workbook
B3: Smooth-tube validation phase: mesh sizing, y+/inflation design, GCI mesh independence, and correlation checks
B6: How this workbook is organized
B7: Inputs
B8: Every number used elsewhere lives here once. Change Re, Tb, growth rate, etc. here and it propagates everywhere via formulas.
B10: Fluid Properties
B11: Syltherm 800 property table + interpolation to your validation bulk temperature (Tb = 500 K). Contains PLACEHOLDER data — see warning below.
B13: YPlus Inflation
B14: Step-by-step y+ calculation (same method as the CFD-Online y+ calculator) and the resulting inflation-layer design: first layer height, growth rate, number of layers.
B16: Mesh Levels
B17: Coarse / Medium / Fine mesh parameters for your 3-level GCI study. Shows exactly what changes between levels and what must stay constant.
B19: Correlation Validation
... B43: Recommended: Re = 100,000, matching your y+ design point. Run the same smooth-tube geometry at coarse/medium/fine mesh density, same Re, same everything else -- only mesh density changes.

Sheet Inputs
B2: Global Inputs
B3: Change values here (blue). Everything else in the workbook references these cells.
B5: Parameter | C5: Value | D5: Units | E5: Notes
B6: Tube inner diameter, D (dti) | C6: 0.066 | D6: m | E6: Locked design value, from CLAUDE.md geometry
B7: Tube length, L | C7: 4 | D7: m | E7: Locked design value (4000 mm)
B8: Re, minimum (validation range) | C8: 5000 | D8: - | E8: From solver_and_formulas.md validation range
B9: Re, maximum (validation range) | C9: 100000 | D9: - | E9: From solver_and_formulas.md validation range -- also the mesh-design worst case
B10: Tb, validation bulk temperature | C10: 500 | D10: K | E10: From solver_and_formulas.md validation plan (Re 5k-100k, Tb=500K)
B11: Target y+ (first inflation layer) | C11: 1 | D11: - | E11: Enhanced Wall Treatment / y+~1 requirement, per solver_and_formulas.md
B12: Inflation growth rate | C12: 1.2 | D12: - | E12: Mid-range of roadmap's suggested 1.1-1.2
B13: Number of inflation layers | C13: 20 | D13: - | E13: Computed to give a sensible total BL thickness -- see YPlus Inflation sheet
B14: Mesh refinement ratio, r (level-to-level) | C14: 1.5 | D14: - | E14: Coarse->Medium->Fine. Celik et al. (2008) recommends r >= 1.3

Sheet Fluid Properties
B2: Syltherm 800 Properties
B3: PLACEHOLDER DATA -- replace rows 6-10 with the exact Dow Chemical datasheet polynomial (Ref [68] in your proposal) before trusting any downstream number. Values below are approximate figures I recall from Dow's public Syltherm 800 technical bulletin, not the verified coefficients your nanofluids_and_properties.md refers to.
B5: T (°C) | C5: T (K) | D5: ρ Density (kg/m³) | E5: ν Kin. Visc. (cSt) | F5: k Therm. Cond. (W/m·K) | G5: cp Spec. Heat (kJ/kg·K)
B6: 0 | C6: =B6+273.15 | D6: 943 | E6: 9.4 | F6: 0.135 | G6: 1.53
B7: 100 | C7: =B7+273.15 | D7: 868 | E7: 1.75 | F7: 0.123 | G7: 1.72
B8: 200 | C8: =B8+273.15 | D8: 792 | E8: 0.72 | F8: 0.111 | G8: 1.92
B9: 300 | C9: =B9+273.15 | D9: 715 | E9: 0.39 | F9: 0.099 | G9: 2.14
B10: 400 | C10: =B10+273.15 | D10: 631 | E10: 0.24 | F10: 0.087 | G10: 2.38
B12: Source: approximate values only -- see warning above. Replace with Ref [68].
B14: Design Point (used everywhere else in this workbook)
B15: Tb (K) | C15: =Inputs!$C$10
B16: Tb (°C) | C16: =C15-273.15
B17: ρ interpolated (kg/m³) | C17: =FORECAST(C16,OFFSET($D$6,MATCH(C16,$B$6:$B$10,1)-1,0,2,1),OFFSET($B$6,MATCH(C16,$B$6:$B$10,1)-1,0,2,1))
B18: ν interpolated (cSt) | C18: =FORECAST(C16,OFFSET($E$6,MATCH(C16,$B$6:$B$10,1)-1,0,2,1),OFFSET($B$6,MATCH(C16,$B$6:$B$10,1)-1,0,2,1))
B19: k interpolated (W/m·K) | C19: =FORECAST(C16,OFFSET($F$6,MATCH(C16,$B$6:$B$10,1)-1,0,2,1),OFFSET($B$6,MATCH(C16,$B$6:$B$10,1)-1,0,2,1))
B20: cp interpolated (kJ/kg·K) | C20: =FORECAST(C16,OFFSET($G$6,MATCH(C16,$B$6:$B$10,1)-1,0,2,1),OFFSET($B$6,MATCH(C16,$B$6:$B$10,1)-1,0,2,1))
B21: μ dynamic viscosity (Pa·s) = ν(cSt)×1e-6×ρ | C21: =C18*0.000001*C17
B22: ν kinematic viscosity (m²/s) | C22: =C18*0.000001
B23: cp (J/kg·K) | C23: =C20*1000
B24: Pr Prandtl number = cp·μ/k | C24: =C23*C21/C19

Sheet YPlus Inflation
B2: y+ Calculation and Inflation-Layer Design
B3: Same method as the CFD-Online y+ calculator: Re -> V -> friction factor -> wall shear -> friction velocity -> first-layer height for target y+.
B5: Parameter | C5: Re = min | D5: Re = max (DESIGN CASE)
B6: Re | C6: =Inputs!$C$8 | D6: =Inputs!$C$9
B7: D (m) | C7: =Inputs!$C$6 | D7: =Inputs!$C$6
B8: ν (m²/s) | C8: ='Fluid Properties'!$C$22 | D8: ='Fluid Properties'!$C$22
B9: ρ (kg/m³) | C9: ='Fluid Properties'!$C$17 | D9: ='Fluid Properties'!$C$17
B10: Velocity V = Re·ν / D (m/s) | C10: =C6*C8/C7 | D10: =D6*D8/D7
B11: Darcy friction factor, f (Petukhov: (0.79·ln(Re)-1.64)^-2) | C11: =(0.79*LN(C6)-1.64)^-2 | D11: =(0.79*LN(D6)-1.64)^-2
B12: Wall shear stress τw = (f/8)·ρ·V² (Pa) | C12: =(C11/8)*C9*C10^2 | D12: =(D11/8)*D9*D10^2
B13: Friction velocity uτ = √(τw/ρ) (m/s) | C13: =SQRT(C12/C9) | D13: =SQRT(D12/D9)
B14: First layer height for y+ = target (m) = y+ · ν / uτ | C14: =Inputs!$C$11*C8/C13 | D14: =Inputs!$C$11*D8/D13
B15: First layer height (mm) | C15: =C14*1000 | D15: =D14*1000
B16: First layer height (µm) | C16: =C14*1000000 | D16: =D14*1000000
B19: DESIGN VALUES -- enter these directly into ANSYS Meshing's Inflation control
B20: First layer height, worst case Re=max (mm) | C20: =D15
B21: First layer height (µm) -- what you'll type into ANSYS (First Layer Thickness) | C21: =C20*1000
B22: Growth rate (input on Inputs sheet) | C22: =Inputs!$C$12
B23: Number of inflation layers (input on Inputs sheet) | C23: =Inputs!$C$13
B24: Total inflation stack thickness (mm) = a·(rⁿ-1)/(r-1) | C24: =C20*(C22^C23-1)/(C22-1)
B25: Tube radius (mm) -- sanity-check denominator | C25: =Inputs!$C$6*1000/2
B26: Inflation stack as % of tube radius (aim ~5-20%) | C26: =C24/C25
B28: Why the first-layer height stays constant across coarse/medium/fine meshes: y+ is a physics requirement tied to Re and the boundary layer thickness, not a numerical discretisation choice. If you change it between mesh levels, a change in your Nu/f results could be caused by the near-wall resolution changing instead of the overall mesh density -- that breaks the mesh-independence test. Only the core/away-from-wall divisions (Mesh Levels sheet) should vary.

Sheet Mesh Levels
B2: Mesh Levels — Coarse / Medium / Fine
B3: Blue cells (Coarse column) are the only ones you type. Medium and Fine are computed by multiplying by the refinement ratio r (Inputs sheet) -- this is what gives you a clean, defensible r for the GCI calculation later, instead of picking mesh sizes by feel.
B5: Refinement ratio, r (from Inputs sheet) | C5: =Inputs!$C$14
B7: Parameter | C7: Coarse (Level 3) | D7: Medium (Level 2) | E7: Fine (Level 1)
B8: Circumferential divisions (around the O-grid perimeter) | C8: 15 | D8: =ROUND(C8*$C$5,0) | E8: =ROUND(D8*$C$5,0)
B9: Core (O-grid centre square) radial divisions | C9: 10 | D9: =ROUND(C9*$C$5,0) | E9: =ROUND(D9*$C$5,0)
B10: Axial divisions (along the 4 m tube length) | C10: 100 | D10: =ROUND(C10*$C$5,0) | E10: =ROUND(D10*$C$5,0)
B12: Approx. circumferential cell size (mm) = π·D / N_circ | C12: =PI()*Inputs!$C$6*1000/C8 | D12: =PI()*Inputs!$C$6*1000/D8 | E12: =PI()*Inputs!$C$6*1000/E8
B13: Approx. axial cell length (mm) = L / N_axial | C13: =Inputs!$C$7*1000/C10 | D13: =Inputs!$C$7*1000/D10 | E13: =Inputs!$C$7*1000/E10
B15: Core-radial cell size -- needs one assumption circumferential/axial didn't: how big is the O-grid centre square?
B16: Core block half-width, as a fraction of tube radius (editable -- common O-grid practice is 0.35-0.45, not a strict rule) | C16: 0.4
B17: Tube radius (mm) | C17: =Inputs!$C$6*1000/2
B18: Core block half-width (mm) = fraction × radius | C18: =C16*C17
B19: Radial (wedge) span (mm) = radius - core half-width | C19: =C17-C18
B20: Approx. core-radial cell size (mm) = wedge span / N_core | C20: =$C$19/C9 | D20: =$C$19/D9 | E20: =$C$19/E9
B21: This is a planning estimate, not a guarantee of what ANSYS's automatic MultiZone O-grid will build -- MultiZone decides the actual core-block position and the size transition itself. Its purpose here is bookkeeping: it feeds the cell-count and representative-size formulas below so your GCI refinement ratio stays consistent across levels. If ANSYS reports poor skewness/orthogonal quality in the wedge blocks after meshing, that's the real signal to adjust the core fraction or Core radial divisions -- not this number on its own.
B23: Inflation (boundary layer) settings — CONSTANT across all three levels, do NOT change these between runs
B24: First layer height (mm) | C24: ='YPlus Inflation'!$C$20 | D24: ='YPlus Inflation'!$C$20 | E24: ='YPlus Inflation'!$C$20
B25: Growth rate | C25: ='YPlus Inflation'!$C$22 | D25: ='YPlus Inflation'!$C$22 | E25: ='YPlus Inflation'!$C$22
B26: Number of inflation layers | C26: ='YPlus Inflation'!$C$23 | D26: ='YPlus Inflation'!$C$23 | E26: ='YPlus Inflation'!$C$23
B28: Approx. total cell count (order-of-magnitude estimate) = N_circ × N_axial × (N_core + N_inflation_layers) | C28: =C8*C10*(C9+C26) | D28: =D8*D10*(D9+D26) | E28: =E8*E10*(E9+E26)
B29: Representative cell size h (mm) = (tube volume / N_total)^(1/3) [used for the GCI refinement-ratio check on the next sheet] | C29: =(PI()/4*(Inputs!$C$6*1000)^2*(Inputs!$C$7*1000)/C28)^(1/3) | D29: =(PI()/4*(Inputs!$C$6*1000)^2*(Inputs!$C$7*1000)/D28)^(1/3) | E29: =(PI()/4*(Inputs!$C$6*1000)^2*(Inputs!$C$7*1000)/E28)^(1/3)
B31: What to change between levels: circumferential divisions, core-block radial divisions, and axial divisions (rows above) -- these control the mesh away from the wall. What must stay fixed: first-layer height, growth rate, number of inflation layers (blue-shaded block above) -- these are a physics requirement (y+), not a discretisation choice. In ANSYS Meshing this maps to: change the Sizing/Method divisions per level; leave the Inflation control's 'First Layer Thickness', 'Growth Rate' and 'Number of Layers' identical in all three.

Sheet Results Calculator
B2: Results Calculator -- one place for h, Nu, dP, f
B3: One row per Fluent run. Paste T_out, T_wall, p_in, p_out here from your Report Definitions (Compute button) -- V, Tb, h, Nu, dP and f compute automatically. The GCI sheet and Correlation Validation sheet both read their Nu/f from this table, so you only enter raw numbers once, here.
B5: Run | C5: Re | D5: q'' (W/m2) | E5: T_out (K) PASTE | F5: T_wall (K) PASTE | G5: p_in (Pa) PASTE | H5: p_out (Pa) PASTE | I5: V (m/s) | J5: Tb (K) | K5: h (W/m2K) | L5: Nu | M5: dP (Pa) | N5: f
B6: GCI -- Fine mesh (Re=100,000 design point) | C6: 100000 | D6: ='GCI Mesh Independence'!$C$8 | E6: 500.93989 | F6: 506.45377 | G6: 368.57945 | H6: 0 | I6: =C6*'Fluid Properties'!$C$22/Inputs!$C$6 | J6: =IF(E6="","",(Inputs!$C$10+E6)/2) | K6: =IF(OR(F6="",J6=""),"",D6/(F6-J6)) | L6: =IF(K6="","",K6*Inputs!$C$6/'Fluid Properties'!$C$19) | M6: =IF(OR(G6="",H6=""),"",G6-H6) | N6: =IF(M6="","",2*M6*Inputs!$C$6/(Inputs!$C$7*'Fluid Properties'!$C$17*I6^2))
B7: GCI -- Medium mesh (Re=100,000 design point) | C7: 100000 | D7: ='GCI Mesh Independence'!$C$8 | E7: 500.9411 | F7: 506.1672 | G7: 364.59766 | H7: 0 | I7: =C7*'Fluid Properties'!$C$22/Inputs!$C$6 | J7: =IF(E7="","",(Inputs!$C$10+E7)/2) | K7: =IF(OR(F7="",J7=""),"",D7/(F7-J7)) | L7: =IF(K7="","",K7*Inputs!$C$6/'Fluid Properties'!$C$19) | M7: =IF(OR(G7="",H7=""),"",G7-H7) | N7: =IF(M7="","",2*M7*Inputs!$C$6/(Inputs!$C$7*'Fluid Properties'!$C$17*I7^2))
B8: GCI -- Coarse mesh (Re=100,000 design point) | C8: 100000 | D8: ='GCI Mesh Independence'!$C$8 | E8: 500.87822 | F8: 505.15696 | G8: 411.29993 | H8: 0 | I8: =C8*'Fluid Properties'!$C$22/Inputs!$C$6 | J8: =IF(E8="","",(Inputs!$C$10+E8)/2) | K8: =IF(OR(F8="",J8=""),"",D8/(F8-J8)) | L8: =IF(K8="","",K8*Inputs!$C$6/'Fluid Properties'!$C$19) | M8: =IF(OR(G8="",H8=""),"",G8-H8) | N8: =IF(M8="","",2*M8*Inputs!$C$6/(Inputs!$C$7*'Fluid Properties'!$C$17*I8^2))
B9: Correlation Validation Re sweep (Tin = 500K design point held fixed for every point)
B10: Correlation Validation -- Re=5,000 | C10: 5000 | D10: ='GCI Mesh Independence'!$C$8 | I10: =C10*'Fluid Properties'!$C$22/Inputs!$C$6 | J10: =IF(E10="","",(Inputs!$C$10+E10)/2) | K10: =IF(OR(F10="",J10=""),"",D10/(F10-J10)) | L10: =IF(K10="","",K10*Inputs!$C$6/'Fluid Properties'!$C$19) | M10: =IF(OR(G10="",H10=""),"",G10-H10) | N10: =IF(M10="","",2*M10*Inputs!$C$6/(Inputs!$C$7*'Fluid Properties'!$C$17*I10^2))
B11: Correlation Validation -- Re=7,500 | C11: 7500 | D11: ='GCI Mesh Independence'!$C$8 | I11: =C11*'Fluid Properties'!$C$22/Inputs!$C$6 | J11: =IF(E11="","",(Inputs!$C$10+E11)/2) | K11: =IF(OR(F11="",J11=""),"",D11/(F11-J11)) | L11: =IF(K11="","",K11*Inputs!$C$6/'Fluid Properties'!$C$19) | M11: =IF(OR(G11="",H11=""),"",G11-H11) | N11: =IF(M11="","",2*M11*Inputs!$C$6/(Inputs!$C$7*'Fluid Properties'!$C$17*I11^2))
B12: Correlation Validation -- Re=10,000 | C12: 10000 | D12: ='GCI Mesh Independence'!$C$8 | I12: =C12*'Fluid Properties'!$C$22/Inputs!$C$6 | J12: =IF(E12="","",(Inputs!$C$10+E12)/2) | K12: =IF(OR(F12="",J12=""),"",D12/(F12-J12)) | L12: =IF(K12="","",K12*Inputs!$C$6/'Fluid Properties'!$C$19) | M12: =IF(OR(G12="",H12=""),"",G12-H12) | N12: =IF(M12="","",2*M12*Inputs!$C$6/(Inputs!$C$7*'Fluid Properties'!$C$17*I12^2))
B13: Correlation Validation -- Re=20,000 | C13: 20000 | D13: ='GCI Mesh Independence'!$C$8 | I13: =C13*'Fluid Properties'!$C$22/Inputs!$C$6 | J13: =IF(E13="","",(Inputs!$C$10+E13)/2) | K13: =IF(OR(F13="",J13=""),"",D13/(F13-J13)) | L13: =IF(K13="","",K13*Inputs!$C$6/'Fluid Properties'!$C$19) | M13: =IF(OR(G13="",H13=""),"",G13-H13) | N13: =IF(M13="","",2*M13*Inputs!$C$6/(Inputs!$C$7*'Fluid Properties'!$C$17*I13^2))
B14: Correlation Validation -- Re=30,000 | C14: 30000 | D14: ='GCI Mesh Independence'!$C$8 | I14: =C14*'Fluid Properties'!$C$22/Inputs!$C$6 | J14: =IF(E14="","",(Inputs!$C$10+E14)/2) | K14: =IF(OR(F14="",J14=""),"",D14/(F14-J14)) | L14: =IF(K14="","",K14*Inputs!$C$6/'Fluid Properties'!$C$19) | M14: =IF(OR(G14="",H14=""),"",G14-H14) | N14: =IF(M14="","",2*M14*Inputs!$C$6/(Inputs!$C$7*'Fluid Properties'!$C$17*I14^2))
B15: Correlation Validation -- Re=50,000 | C15: 50000 | D15: ='GCI Mesh Independence'!$C$8 | I15: =C15*'Fluid Properties'!$C$22/Inputs!$C$6 | J15: =IF(E15="","",(Inputs!$C$10+E15)/2) | K15: =IF(OR(F15="",J15=""),"",D15/(F15-J15)) | L15: =IF(K15="","",K15*Inputs!$C$6/'Fluid Properties'!$C$19) | M15: =IF(OR(G15="",H15=""),"",G15-H15) | N15: =IF(M15="","",2*M15*Inputs!$C$6/(Inputs!$C$7*'Fluid Properties'!$C$17*I15^2))
B16: Correlation Validation -- Re=70,000 | C16: 70000 | D16: ='GCI Mesh Independence'!$C$8 | I16: =C16*'Fluid Properties'!$C$22/Inputs!$C$6 | J16: =IF(E16="","",(Inputs!$C$10+E16)/2) | K16: =IF(OR(F16="",J16=""),"",D16/(F16-J16)) | L16: =IF(K16="","",K16*Inputs!$C$6/'Fluid Properties'!$C$19) | M16: =IF(OR(G16="",H16=""),"",G16-H16) | N16: =IF(M16="","",2*M16*Inputs!$C$6/(Inputs!$C$7*'Fluid Properties'!$C$17*I16^2))
B17: Correlation Validation -- Re=100,000 | C17: 100000 | D17: ='GCI Mesh Independence'!$C$8 | I17: =C17*'Fluid Properties'!$C$22/Inputs!$C$6 | J17: =IF(E17="","",(Inputs!$C$10+E17)/2) | K17: =IF(OR(F17="",J17=""),"",D17/(F17-J17)) | L17: =IF(K17="","",K17*Inputs!$C$6/'Fluid Properties'!$C$19) | M17: =IF(OR(G17="",H17=""),"",G17-H17) | N17: =IF(M17="","",2*M17*Inputs!$C$6/(Inputs!$C$7*'Fluid Properties'!$C$17*I17^2))
B19: q'' pulls from the single wall-heat-flux input on the GCI sheet -- keep it identical across every run. V = Re . nu / D (kinematic viscosity, Fluid Properties sheet). f uses this row's own V, so it is correct at every Re, not just the Re=100,000 GCI design point.

Sheet Correlation Validation
B2: Smooth-Tube Validation vs Gnielinski / Petukhov
B3: Nu CFD and f CFD pull automatically from the Results Calculator sheet (enter your raw T_out/T_wall/p_in/p_out there, per Re). Deviation % and PASS/FAIL compute automatically against the thresholds in your solver_and_formulas.md (Nu <= 9%, f <= 5%).
B5: Re | C5: f Petukhov (target) | D5: Nu Gnielinski (target) | E5: Nu Dittus- Boelter (ref.) | F5: Nu CFD (fill in) | G5: Nu dev. % | H5: f CFD (fill in) | I5: f dev. %
B6: 5000 | C6: =(0.79*LN(B6)-1.64)^-2 | D6: =(C6/8)*(B6-1000)*'Fluid Properties'!$C$24/(1+12.7*(C6/8)^0.5*('Fluid Properties'!$C$24^(2/3)-1)) | E6: =0.023*B6^0.8*'Fluid Properties'!$C$24^0.4 | F6: =IF('Results Calculator'!L10="","",'Results Calculator'!L10) | G6: =IF(F6="","",ABS(F6-D6)/D6) | H6: =IF('Results Calculator'!N10="","",'Results Calculator'!N10) | I6: =IF(H6="","",ABS(H6-C6)/C6)
B7: 7500 | C7: =(0.79*LN(B7)-1.64)^-2 | D7: =(C7/8)*(B7-1000)*'Fluid Properties'!$C$24/(1+12.7*(C7/8)^0.5*('Fluid Properties'!$C$24^(2/3)-1)) | E7: =0.023*B7^0.8*'Fluid Properties'!$C$24^0.4 | F7: =IF('Results Calculator'!L11="","",'Results Calculator'!L11) | G7: =IF(F7="","",ABS(F7-D7)/D7) | H7: =IF('Results Calculator'!N11="","",'Results Calculator'!N11) | I7: =IF(H7="","",ABS(H7-C7)/C7)
B8: 10000 | C8: =(0.79*LN(B8)-1.64)^-2 | D8: =(C8/8)*(B8-1000)*'Fluid Properties'!$C$24/(1+12.7*(C8/8)^0.5*('Fluid Properties'!$C$24^(2/3)-1)) | E8: =0.023*B8^0.8*'Fluid Properties'!$C$24^0.4 | F8: =IF('Results Calculator'!L12="","",'Results Calculator'!L12) | G8: =IF(F8="","",ABS(F8-D8)/D8) | H8: =IF('Results Calculator'!N12="","",'Results Calculator'!N12) | I8: =IF(H8="","",ABS(H8-C8)/C8)
B9: 20000 | C9: =(0.79*LN(B9)-1.64)^-2 | D9: =(C9/8)*(B9-1000)*'Fluid Properties'!$C$24/(1+12.7*(C9/8)^0.5*('Fluid Properties'!$C$24^(2/3)-1)) | E9: =0.023*B9^0.8*'Fluid Properties'!$C$24^0.4 | F9: =IF('Results Calculator'!L13="","",'Results Calculator'!L13) | G9: =IF(F9="","",ABS(F9-D9)/D9) | H9: =IF('Results Calculator'!N13="","",'Results Calculator'!N13) | I9: =IF(H9="","",ABS(H9-C9)/C9)
B10: 30000 | C10: =(0.79*LN(B10)-1.64)^-2 | D10: =(C10/8)*(B10-1000)*'Fluid Properties'!$C$24/(1+12.7*(C10/8)^0.5*('Fluid Properties'!$C$24^(2/3)-1)) | E10: =0.023*B10^0.8*'Fluid Properties'!$C$24^0.4 | F10: =IF('Results Calculator'!L14="","",'Results Calculator'!L14) | G10: =IF(F10="","",ABS(F10-D10)/D10) | H10: =IF('Results Calculator'!N14="","",'Results Calculator'!N14) | I10: =IF(H10="","",ABS(H10-C10)/C10)
B11: 50000 | C11: =(0.79*LN(B11)-1.64)^-2 | D11: =(C11/8)*(B11-1000)*'Fluid Properties'!$C$24/(1+12.7*(C11/8)^0.5*('Fluid Properties'!$C$24^(2/3)-1)) | E11: =0.023*B11^0.8*'Fluid Properties'!$C$24^0.4 | F11: =IF('Results Calculator'!L15="","",'Results Calculator'!L15) | G11: =IF(F11="","",ABS(F11-D11)/D11) | H11: =IF('Results Calculator'!N15="","",'Results Calculator'!N15) | I11: =IF(H11="","",ABS(H11-C11)/C11)
B12: 70000 | C12: =(0.79*LN(B12)-1.64)^-2 | D12: =(C12/8)*(B12-1000)*'Fluid Properties'!$C$24/(1+12.7*(C12/8)^0.5*('Fluid Properties'!$C$24^(2/3)-1)) | E12: =0.023*B12^0.8*'Fluid Properties'!$C$24^0.4 | F12: =IF('Results Calculator'!L16="","",'Results Calculator'!L16) | G12: =IF(F12="","",ABS(F12-D12)/D12) | H12: =IF('Results Calculator'!N16="","",'Results Calculator'!N16) | I12: =IF(H12="","",ABS(H12-C12)/C12)
B13: 100000 | C13: =(0.79*LN(B13)-1.64)^-2 | D13: =(C13/8)*(B13-1000)*'Fluid Properties'!$C$24/(1+12.7*(C13/8)^0.5*('Fluid Properties'!$C$24^(2/3)-1)) | E13: =0.023*B13^0.8*'Fluid Properties'!$C$24^0.4 | F13: =IF('Results Calculator'!L17="","",'Results Calculator'!L17) | G13: =IF(F13="","",ABS(F13-D13)/D13) | H13: =IF('Results Calculator'!N17="","",'Results Calculator'!N17) | I13: =IF(H13="","",ABS(H13-C13)/C13)
B15: Thresholds source: solver_and_formulas.md, 'Expected agreement: Nu <= ~9% max deviation, f <= ~5% max deviation'. Pr held fixed at the Tb=500K design point (Fluid Properties sheet) for this whole sweep, matching the validation plan in CLAUDE.md ('Re 5k-100k, Tb=500K'). Dittus-Boelter column is a secondary reference only (per your roadmap doc) -- Gnielinski is the primary target because it is valid over your full Re range and is what CLAUDE.md specifies.

Sheet GCI Mesh Independence
B2: Grid Convergence Index (Celik et al. 2008)
B3: Run your smooth-tube geometry at ALL THREE mesh levels (Mesh Levels sheet), at ONE fixed Re (recommended: 100,000, your y+ design point). Enter your raw T_out/T_wall/p_in/p_out on the Results Calculator sheet (rows 6-8) -- everything below pulls from there automatically.
B5: Validation Re used for this mesh-independence study | C5: 100000
B7: Raw Fluent Extraction (linked from Results Calculator -- enter raw numbers there, rows 6-8)
B8: Wall heat flux, q'' (W/m²) -- must match your Fluent Wall BC, same for every mesh level | C8: 5000
B10: Parameter | C10: Fine (1) | D10: Medium (2) | E10: Coarse (3)
B11: Outlet bulk temperature, T_out (K) -- linked from Results Calculator | C11: =IF('Results Calculator'!E6="","",'Results Calculator'!E6) | D11: =IF('Results Calculator'!E7="","",'Results Calculator'!E7) | E11: =IF('Results Calculator'!E8="","",'Results Calculator'!E8)
B12: Wall temperature, T_wall (K) -- linked from Results Calculator | C12: =IF('Results Calculator'!F6="","",'Results Calculator'!F6) | D12: =IF('Results Calculator'!F7="","",'Results Calculator'!F7) | E12: =IF('Results Calculator'!F8="","",'Results Calculator'!F8)
B13: Inlet pressure, p_in (Pa) -- linked from Results Calculator | C13: =IF('Results Calculator'!G6="","",'Results Calculator'!G6) | D13: =IF('Results Calculator'!G7="","",'Results Calculator'!G7) | E13: =IF('Results Calculator'!G8="","",'Results Calculator'!G8)
B14: Outlet pressure, p_out (Pa) -- linked from Results Calculator | C14: =IF('Results Calculator'!H6="","",'Results Calculator'!H6) | D14: =IF('Results Calculator'!H7="","",'Results Calculator'!H7) | E14: =IF('Results Calculator'!H8="","",'Results Calculator'!H8)
B16: Bulk temperature, Tb = (T_in + T_out) / 2 (K) | C16: =IF(C11="","",(Inputs!$C$10+C11)/2) | D16: =IF(D11="","",(Inputs!$C$10+D11)/2) | E16: =IF(E11="","",(Inputs!$C$10+E11)/2)
B17: Heat transfer coefficient, h = q'' / (T_wall - Tb) (W/m²·K) | C17: =IF(OR(C12="",C16=""),"",$C$8/(C12-C16)) | D17: =IF(OR(D12="",D16=""),"",$C$8/(D12-D16)) | E17: =IF(OR(E12="",E16=""),"",$C$8/(E12-E16))
B18: Nu = h · D / k | C18: =IF(C17="","",C17*Inputs!$C$6/'Fluid Properties'!$C$19) | D18: =IF(D17="","",D17*Inputs!$C$6/'Fluid Properties'!$C$19) | E18: =IF(E17="","",E17*Inputs!$C$6/'Fluid Properties'!$C$19)
B19: Pressure drop, ΔP = p_in - p_out (Pa) | C19: =IF(OR(C13="",C14=""),"",C13-C14) | D19: =IF(OR(D13="",D14=""),"",D13-D14) | E19: =IF(OR(E13="",E14=""),"",E13-E14)
B20: f = 2 · ΔP · D / (L · ρ · V²) | C20: =IF(C19="","",2*C19*Inputs!$C$6/(Inputs!$C$7*'Fluid Properties'!$C$17*'YPlus Inflation'!$D$10^2)) | D20: =IF(D19="","",2*D19*Inputs!$C$6/(Inputs!$C$7*'Fluid Properties'!$C$17*'YPlus Inflation'!$D$10^2)) | E20: =IF(E19="","",2*E19*Inputs!$C$6/(Inputs!$C$7*'Fluid Properties'!$C$17*'YPlus Inflation'!$D$10^2))
B21: V here uses the Re=100,000 design velocity from YPlus Inflation (0.9567 m/s) -- correct as long as this GCI study is run at Re=100,000 (row 5 above). ρ and k come from Fluid Properties at Tb=500K.
B23: Mesh Comparison Summary -- Nu and f across mesh levels (this is where you see the difference)
B24: Parameter | C24: Fine (1) | D24: Medium (2) | E24: Coarse (3)
B25: Nu | C25: =IF(C18="","",C18) | D25: =IF(D18="","",D18) | E25: =IF(E18="","",E18)
B26: f | C26: =IF(C20="","",C20) | D26: =IF(D20="","",D20) | E26: =IF(E20="","",E20)
B28: % change in Nu, Fine -> Medium / Medium -> Coarse | C28: =IF(OR(C25="",D25=""),"",(D25-C25)/C25) | D28: =IF(OR(D25="",E25=""),"",(E25-D25)/D25)
B29: % change in f, Fine -> Medium / Medium -> Coarse | C29: =IF(OR(C26="",D26=""),"",(D26-C26)/C26) | D29: =IF(OR(D26="",E26=""),"",(E26-D26)/D26)
B30: These % changes are a quick visual check while you're entering results. The formal, weighted mesh-independence verdict (GCI%) is computed in the two blocks below -- use GCI%, not this row, to decide pass/fail.
B32: Nusselt Number (Nu) Mesh Independence
B33: Parameter | C33: Fine (1) | D33: Medium (2) | E33: Coarse (3)
B34: Representative cell size, h (mm) | C34: ='Mesh Levels'!$E$29 | D34: ='Mesh Levels'!$D$29 | E34: ='Mesh Levels'!$C$29
B35: Nu result -- auto-computed from Raw Fluent Extraction above | C35: =IF(C18="","",C18) | D35: =IF(D18="","",D18) | E35: =IF(E18="","",E18)
B37: r21 = h2/h1 (medium/fine) | C37: =D34/C34
B38: r32 = h3/h2 (coarse/medium) | C38: =E34/D34
B39: ε21 = φ2 - φ1 | C39: =IF(OR(C35="",D35=""),"",D35-C35)
B40: ε32 = φ3 - φ2 | C40: =IF(OR(D35="",E35=""),"",E35-D35)
B41: Convergence ratio, R = ε21 / ε32 | C41: =IF(OR(C39="",C40=""),"",C39/C40)
B42: Convergence classification | C42: =IF(C41="","",IF(C41<0,"FAIL -- OSCILLATORY (GCI/order below not usable)",IF(ABS(C41)>1,"FAIL -- MONOTONIC DIVERGENCE (GCI/order below not usable)","PASS -- monotonic convergence, GCI below is usable")))
B43: Apparent order, p = ln|ε32/ε21| / ln(r) (exact when r21≈r32, valid here by construction) | C43: =IF(OR(C39="",C40=""),"",LN(ABS(C40/C39))/LN(C37))
B44: Richardson-extrapolated value, φ_ext21 = (r21^p·φ1 - φ2) / (r21^p - 1) | C44: =IF(C43="","",(C37^C43*C35-D35)/(C37^C43-1))
B45: Approximate relative error, e_a21 = |(φ1-φ2)/φ1| | C45: =IF(OR(C35="",D35=""),"",ABS((C35-D35)/C35))
B46: Extrapolated relative error, e_ext21 = |(φ_ext21-φ1)/φ_ext21| | C46: =IF(C44="","",ABS((C44-C35)/C44))
B47: GCI_fine (%) = 1.25 · e_a21 / (r21^p - 1) × 100 | C47: =IF(OR(C43="",C45=""),"",1.25*C45/(C37^C43-1))
B48: Check Convergence classification above FIRST. If it says FAIL, the apparent order p and GCI% here are mathematical artifacts (a negative or unphysical p), not a real result -- do not use them to claim mesh independence. If it says PASS, mesh-independent when GCI_fine < ~1% (CLAUDE.md threshold) to ~2% (roadmap threshold); if it fails, your Fine mesh becomes the new Coarse and you add a finer 4th level.
B50: Friction Factor (f) Mesh Independence
...

Sheet Dudley D1 Validation
B2: Dudley et al. (SAND94-1884) — LS-2 Table D-1 Validation
B3: Receiver-scale (not smooth-tube hydrodynamic) validation. Reproduces the 9 measured cermet/vacuum test cases from reference-data/dudley_table_d1.md. Aperture area A_a = 39.2 m² -- NOT tube surface area (flagged as a common mistake in your own notes).
B5: Aperture area, A_a (m²) | C5: 39.2
B7: Case | C7: DNI (W/m²) | D7: Wind (m/s) | E7: Tin (°C) | F7: Flow (L/min) | G7: Tout meas. (°C) | H7: η_th meas. (%) | I7: Tout CFD (fill in) | J7: η_th CFD (fill in) | K7: dev. %
B8: 1 | C8: 933.7 | D8: 2.6 | E8: 102.2 | F8: 47.7 | G8: 124 | H8: 72.51 | K8: =IF(J8="","",ABS(J8-H8)/H8)
B9: 2 | C9: 968.2 | D9: 3.7 | E9: 151 | F9: 47.8 | G9: 173.3 | H9: 70.9 | K9: =IF(J9="","",ABS(J9-H9)/H9)
B10: 3 | C10: 982.3 | D10: 2.5 | E10: 197.5 | F10: 49.1 | G10: 219.5 | H10: 70.17 | K10: =IF(J10="","",ABS(J10-H10)/H10)
B11: 4 | C11: 906.6 | D11: 3.3 | E11: 250.7 | F11: 54.7 | G11: 269.4 | H11: 70.25 | K11: =IF(J11="","",ABS(J11-H11)/H11)
B12: 5 | C12: 937.9 | D12: 1 | E12: 297.8 | F12: 55.5 | G12: 316.9 | H12: 67.98 | K12: =IF(J12="","",ABS(J12-H12)/H12)
B13: 6 | C13: 880.6 | D13: 2.9 | E13: 299 | F13: 55.6 | G13: 317.2 | H13: 68.92 | K13: =IF(J13="","",ABS(J13-H13)/H13)
B14: 7 | C14: 920.9 | D14: 2.6 | E14: 379.5 | F14: 56.8 | G14: 398 | H14: 62.34 | K14: =IF(J14="","",ABS(J14-H14)/H14)
B15: 8 | C15: 903.2 | D15: 4.2 | E15: 355.9 | F15: 56.3 | G15: 374 | H15: 63.82 | K15: =IF(J15="","",ABS(J15-H15)/H15)
B16: 9 | C16: 920.9 | D16: 2.6 | E16: 379.5 | F16: 56.8 | G16: 398 | H16: 62.34 | K16: =IF(J16="","",ABS(J16-H16)/H16)
B18: η_th = (Q_u - P_p/η_el) / (A_a x I_b), Q_u = m_dot x cp x (Tout-Tin), P_p = pumping power, η_el = 0.3, I_b = DNI. Cases 7 and 9 are identical in the original report (per your notes). Note 7 and 9 are duplicated on purpose -- do not delete either, that mirrors the source report.

Sheet L27 Run Log
B2: L27 Taguchi Production Run Log
B3: Factor columns pre-filled from taguchi/L27_run_matrix.md. Result columns match the tracking sheet your own Learning_Roadmap docx recommends (Phase 5). PEC needs a plain-tube Nu/f reference AT THE SAME Re as these runs -- fill that in below before PEC will compute; your roadmap explicitly warns that comparing enhanced vs. plain tube at different Re invalidates the result.
B5: Plain-tube reference Nu_plain (same Re as production runs, fill in after validation)
B6: Plain-tube reference f_plain (same Re as production runs, fill in after validation)
B8: Run | C8: A Pt/dti | D8: B dpo/dti | E8: C tp/dpo | F8: D Nanofluid | G8: E φ % | H8: Pt (mm) | I8: dpo (mm) | J8: tp (mm) | K8: dpi (mm) | L8: Nu (fill in) | M8: f (fill in) | N8: PEC | O8: ΔP (Pa) (fill in) | P8: Tout (K) (fill in) | Q8: Twall,max (K) (fill in) | R8: Iterations (fill in)
B9: 1 | C9: 3.03 | D9: 0.23 | E9: 0.04 | F9: Fe2O3-GO | G9: 0.5 | H9: 200 | I9: 15 | J9: 0.6 | K9: 13.8 | N9: =IF(OR(L9="",M9="",$G$5="",$G$6=""),"",(L9/$G$5)/(M9/$G$6)^(1/3))
B10: 2 | C10: 3.03 | D10: 0.23 | E10: 0.08 | F10: Al2O3-MWCNT | G10: 1 | H10: 200 | I10: 15 | J10: 1.2 | K10: 12.6 | N10: =IF(OR(L10="",M10="",$G$5="",$G$6=""),"",(L10/$G$5)/(M10/$G$6)^(1/3))
B11: 3 | C11: 3.03 | D11: 0.23 | E11: 0.12 | F11: Ag-MgO | G11: 2 | H11: 200 | I11: 15 | J11: 1.8 | K11: 11.4 | N11: =IF(OR(L11="",M11="",$G$5="",$G$6=""),"",(L11/$G$5)/(M11/$G$6)^(1/3))
B12: 4 | C12: 3.03 | D12: 0.38 | E12: 0.04 | F12: Al2O3-MWCNT | G12: 2 | H12: 200 | I12: 25 | J12: 1 | K12: 23 | N12: =IF(OR(L12="",M12="",$G$5="",$G$6=""),"",(L12/$G$5)/(M12/$G$6)^(1/3))
B13: 5 | C13: 3.03 | D13: 0.38 | E13: 0.08 | F13: Ag-MgO | G13: 0.5 | H13: 200 | I13: 25 | J13: 2 | K13: 21 | N13: =IF(OR(L13="",M13="",$G$5="",$G$6=""),"",(L13/$G$5)/(M13/$G$6)^(1/3))
B14: 6 | C14: 3.03 | D14: 0.38 | E14: 0.12 | F14: Fe2O3-GO | G14: 1 | H14: 200 | I14: 25 | J14: 3 | K14: 19 | N14: =IF(OR(L14="",M14="",$G$5="",$G$6=""),"",(L14/$G$5)/(M14/$G$6)^(1/3))
B15: 7 | C15: 3.03 | D15: 0.53 | E15: 0.04 | F15: Ag-MgO | G15: 1 | H15: 200 | I15: 35 | J15: 1.4 | K15: 32.2 | N15: =IF(OR(L15="",M15="",$G$5="",$G$6=""),"",(L15/$G$5)/(M15/$G$6)^(1/3))
B16: 8 | C16: 3.03 | D16: 0.53 | E16: 0.08 | F16: Fe2O3-GO | G16: 2 | H16: 200 | I16: 35 | J16: 2.8 | K16: 29.4 | N16: =IF(OR(L16="",M16="",$G$5="",$G$6=""),"",(L16/$G$5)/(M16/$G$6)^(1/3))
B17: 9 | C17: 3.03 | D17: 0.53 | E17: 0.12 | F17: Al2O3-MWCNT | G17: 0.5 | H17: 200 | I17: 35 | J17: 4.2 | K17: 26.6 | N17: =IF(OR(L17="",M17="",$G$5="",$G$6=""),"",(L17/$G$5)/(M17/$G$6)^(1/3))
B18: 10 | C18: 4.55 | D18: 0.23 | E18: 0.04 | F18: Al2O3-MWCNT | G18: 1 | H18: 300 | I18: 15 | J18: 0.6 | K18: 13.8 | N18: =IF(OR(L18="",M18="",$G$5="",$G$6=""),"",(L18/$G$5)/(M18/$G$6)^(1/3))
B19: 11 | C19: 4.55 | D19: 0.23 | E19: 0.08 | F19: Ag-MgO | G19: 2 | H19: 300 | I19: 15 | J19: 1.2 | K19: 12.6 | N19: =IF(OR(L19="",M19="",$G$5="",$G$6=""),"",(L19/$G$5)/(M19/$G$6)^(1/3))
B20: 12 | C20: 4.55 | D20: 0.23 | E20: 0.12 | F20: Fe2O3-GO | G20: 0.5 | H20: 300 | I20: 15 | J20: 1.8 | K20: 11.4 | N20: =IF(OR(L20="",M20="",$G$5="",$G$6=""),"",(L20/$G$5)/(M20/$G$6)^(1/3))
... B35: 27 | C35: 6.06 | D35: 0.53 | E35: 0.12 | F35: Fe2O3-GO | G35: 2 | H35: 400 | I35: 35 | J35: 4.2 | K35: 26.6 | N35: =IF(OR(L35="",M35="",$G$5="",$G$6=""),"",(L35/$G$5)/(M35/$G$6)^(1/3))
B37: Each factor level appears exactly 9 times across the 27 runs (Taguchi orthogonal balance) -- do not reorder or edit the factor columns. PEC = (Nu/Nu_plain) / (f/f_plain)^(1/3): PEC > 1 means the enhancement is worth its friction penalty.
