Workbook

Sheet README
A1: PTSC Receiver — GCI & Report Extraction Workbook
A2: Companion file to the Master Thesis Output Map artifact and Report Definitions Mastery course.
A5: Cell color legend
A6: Yellow | B6: Type your Fluent-extracted numbers here (input cells)
A7: Tan / gold | B7: Fixed constants — check these match your case before trusting formulas
A8: Black text | B8: Formulas — do not overwrite, they recalculate automatically
A10: How to use this workbook
A11: 1. | B11: Run your coarse mesh in Fluent, let it converge, read the Report File / Report Plot final values.
A12: 2. | B12: Go to 'Mesh Run Data' tab, type the numbers into the 'Coarse' column (yellow cells only).
A13: 3. | B13: Repeat for Medium and Fine mesh levels as you complete them.
A14: 4. | B14: Open 'Mesh Independence Check' — it recalculates automatically from whatever you've entered.
A15: 5. | B15: Both Nu and ΔP within 2% between the two finest mesh levels = mesh independence achieved. Until then, keep refining (add another mesh column if needed).
A17: Sheets in this workbook
A18: Mesh Run Data | B18: Fill in up to 4 mesh levels here — this is your numeric Master Output Map.
A19: Mesh Independence Check | B19: Auto-computes the consecutive-mesh percent difference for Nu and ΔP, per Mohammed et al. (2022) Table 4 -- not Richardson extrapolation.
A20: Report Definition Reference | B20: Which Fluent report/type/surface each quantity comes from — the descriptive map, for lookup.
A21: Figures & Output Parameters | B21: Contours, vectors, streamlines, XY plots, and when Create Output Parameter is actually worth using.
A23: Important assumption — read before trusting the GCI numbers
B24: Method note: this workbook uses the simple consecutive-mesh percent-difference method from Mohammed et al. (2022), Table 4 -- not the Celik et al. (2008) Richardson-extrapolation GCI method.
B25: This matches how your advisor's own published paper accepted mesh independence: compare the two finest levels, and stop once the difference is below 2% -- no monotonicity or apparent-order requirement.
B26: The paper itself adopted the SECOND-FINEST of its 4 mesh levels once that comparison cleared 2%, not always the very finest -- keep that precedent in mind.

Sheet Mesh Run Data
A1: Mesh Run Data — Mesh Independence Study
A2: Type Fluent output values into the yellow cells only. Formula rows (black) recalculate automatically. Method: consecutive-mesh percent difference (Mohammed et al. 2022 style), not Richardson extrapolation.
A4: Fixed constants (check before trusting formulas)
A5: d_ri | B5: Absorber tube inner diameter | C5: 0.066 | D5: m | E5: CLAUDE.md — LS-2 geometry, dti = 66 mm
A6: rho_f | B6: Fluid density (Syltherm 800, reference) | C6: 747.2 | D6: kg/m³ | E6: solver_and_formulas.md Table 14 — update if evaluating at a different bulk T
A7: k_f | B7: Fluid thermal conductivity (Syltherm 800, reference) | C7: 0.0961 | D7: W/m·K | E7: solver_and_formulas.md Table 14 — update if evaluating at a different bulk T
A8: dpo | B8: Promoter outer size (this GCI geometry) | C8: 0.025 | D8: m | E8: User-confirmed: dpo = 25 mm (Level 2) -- check against taguchi/L27_run_matrix.md if this GCI run changes
A9: tp | B9: Promoter wall thickness (this GCI geometry) | C9: 0.002 | D9: m | E9: User-confirmed: tp = 2 mm (Level 2) -- check against taguchi/L27_run_matrix.md if this GCI run changes
A10: dpi | B10: Promoter inner (hollow) size | C10: =$C$8-2*$C$9 -> 0.021 | D10: m | E10: Formula: dpo - 2 x tp
A11: A_annulus | B11: Annulus flow area = tube bore minus promoter footprint | C11: =PI()*$C$5^2/4-$C$8^2 -> 0.0027961944 | D11: m² | E11: Formula: (pi x d_ri^2 / 4) - dpo^2 -- exact regardless of twist (rotation preserves area)
A12: A_core | B12: Core (hollow) flow area | C12: =$C$10^2 -> 0.000441 | D12: m² | E12: Formula: dpi^2
A13: A_total | B13: Total flow area (annulus + core) | C13: =$C$11+$C$12 -> 0.0032371944 | D13: m² | E13: Formula: A_annulus + A_core -- feeds u_m via continuity
A15: Quantity | B15: Symbol | C15: Unit | D15: Mesh 1 (Coarsest) | E15: Mesh 2 | F15: Mesh 3 | G15: Mesh 4 (Finest) | H15: Notes
A16: MESH
A17: Cell Count (Elements) | B17: N | C17: count | D17: 2718404 | E17: 4888550 | F17: 8658088 | G17: 15675184 | H17: Mesh Report → Cell Count (fluid_domain)
A18: Nodes | B18: — | C18: count | D18: 1270568 | E18: 2212552 | F18: 3761583 | G18: 6571364 | H18: Mesh → Statistics → Nodes (NOT a Report Definition)
A19: y+ average | B19: y+_avg | C19: — | D19: 0.28976573 | E19: 0.28853973 | F19: 0.28587271 | G19: 0.28596802 | H19: Surface Report, Area-Wtd Avg, Wall Yplus, tube_wall_inner_interface, at highest Re
A20: y+ maximum | B20: y+_max | C20: — | D20: 2.2616925 | E20: 2.2067659 | F20: 2.1208642 | G20: 1.638528 | H20: Surface Report, Facet Maximum, Wall Yplus, same surface
A21: Max skewness | B21: — | C21: — | D21: 0.883 | E21: 0.84786 | F21: 0.84981 | G21: 0.8499 | H21: Mesh → Quality panel. Target < 0.95 (0.80-0.95 = 'bad' per ANSYS guidance, still watch it)
A22: Min orthogonal quality | B22: — | C22: — | D22: 0.009 | E22: 0.012928 | F22: 0.014979 | G22: 0.013121 | H22: Mesh → Quality panel. Target > 0.01 -- flag if lower, check WHERE the worst cell sits
A23: Inflation aspect ratio | B23: — | C23: — | H23: Mesh → Quality panel (NOT a Report Definition)
A24: TEMPERATURE
A25: Inlet temperature | B25: T_in | C25: K | D25: 300 | E25: 300 | F25: 300 | G25: 300 | H25: Surface Report, Mass-Wtd Avg, Static Temp, both inlet faces
A26: Outlet temperature | B26: T_out | C26: K | D26: 300.10916 | E26: 300.10897 | F26: 300.10891 | G26: 300.10884 | H26: Surface Report, Mass-Wtd Avg, Static Temp, both outlet faces
A27: Wall temperature (T_ri) | B27: T_wall | C27: K | D27: 300.79988 | E27: 300.79507 | F27: 300.80989 | G27: 300.81887 | H27: Surface Report, Area-Wtd Avg, Static Temp, tube_wall_inner_interface
A28: Bulk temperature | B28: T_b | C28: K | D28: =(D25+D26)/2 -> 300.05458 | E28: =(E25+E26)/2 -> 300.05448 | F28: =(F25+F26)/2 -> 300.05446 | G28: =(G25+G26)/2 -> 300.05442 | H28: Formula: (T_in + T_out) / 2
A29: PRESSURE & FLOW
A30: Inlet pressure | B30: p_in | C30: Pa | D30: 3604.2315 | E30: 3551.4899 | F30: 3443.4149 | G30: 3480.9322 | H30: Surface Report, Area-Wtd Avg, Static Pressure, both inlet faces
A31: Outlet pressure | B31: p_out | C31: Pa | D31: 0 | E31: 0 | F31: 0 | G31: 0 | H31: Surface Report, Area-Wtd Avg, Static Pressure, both outlet faces
A32: Pressure drop | B32: ΔP | C32: Pa | D32: =IF(OR(D30="",D31=""),"",D30-D31) -> 3604.2315 | E32: =IF(OR(E30="",E31=""),"",E30-E31) -> 3551.4899 | F32: =IF(OR(F30="",F31=""),"",F30-F31) -> 3443.4149 | G32: =IF(OR(G30="",G31=""),"",G30-G31) -> 3480.9322 | H32: Formula: p_in minus p_out
A33: Wall shear stress | B33: τ_w | C33: Pa | D33: 6.7540564 | E33: 6.6431553 | F33: 6.4316542 | G33: 6.4239878 | H33: Surface Report, Area-Wtd Avg, Wall Fluxes → Wall Shear Stress
A34: Mass flow rate — inlet | B34: ṁ_in | C34: kg/s | D34: 4.1037732 | E34: 4.1101779 | F34: 4.1141516 | G34: 4.1164599 | H34: Surface/Flux Report, Mass Flow Rate, both inlet faces (core + annulus)
A35: Mass flow rate — outlet | B35: ṁ_out | C35: kg/s | D35: 4.1038324 | E35: 4.110226 | F35: 4.1141649 | G35: 4.1164741 | H35: Surface/Flux Report, Mass Flow Rate, both outlet faces (core + annulus)
A36: Mean velocity | B36: u_m | C36: m/s | D36: =IFERROR(D34/($C$6*$C$13),"") -> 1.6965931 | E36: =IFERROR(E34/($C$6*$C$13),"") -> 1.699241 | F36: =IFERROR(F34/($C$6*$C$13),"") -> 1.7008838 | G36: =IFERROR(G34/($C$6*$C$13),"") -> 1.7018381 | H36: Formula: mdot_in / (rho x A_total) -- via continuity, using this run's dpo/tp geometry
A37: Friction factor | B37: f | C37: — | D37: =IFERROR(2*D33/($C$6*D36^2),"") -> 0.0062806183 | E37: =IFERROR(2*E33/($C$6*E36^2),"") -> 0.0061582538 | F37: =IFERROR(2*F33/($C$6*F36^2),"") -> 0.005950679 | G37: =IFERROR(2*G33/($C$6*G36^2),"") -> 0.0059369221 | H37: Formula: 2 x tau_w / (rho x u_m^2)
A38: Mass balance error | B38: — | C38: % | D38: =IFERROR(ABS(D34-D35)/D34*100,"") -> 0.0014425748 | E38: =IFERROR(ABS(E34-E35)/E34*100,"") -> 0.0011702656 | F38: =IFERROR(ABS(F34-F35)/F34*100,"") -> 0.00032327443 | G38: =IFERROR(ABS(G34-G35)/G34*100,"") -> 0.0003449566 | H38: Should be very small (<0.1%) at true convergence
A39: HEAT TRANSFER
A40: Wall heat flux (avg) | B40: q" | C40: W/m² | D40: 1000 | E40: 1000 | F40: 1000 | G40: 1000 | H40: Surface Report, Area-Wtd Avg, Wall Fluxes → Total Surface Heat Flux
A41: Total heat transfer rate | B41: Q̇ | C41: W | D41: 879.09725 | E41: 879.32023 | F41: 879.45348 | G41: 879.53198 | H41: Flux Report, Total Heat Transfer Rate, both absorber walls
A42: Heat transfer coefficient | B42: h | C42: W/m²K | D42: =IFERROR(D40/(D27-D28),"") -> 1341.7416 | E42: =IFERROR(E40/(E27-E28),"") -> 1350.2839 | F42: =IFERROR(F40/(F27-F28),"") -> 1323.7406 | G42: =IFERROR(G40/(G27-G28),"") -> 1308.13 | H42: Formula: q_flux / (T_wall minus T_b) -- built manually, not Fluent's built-in h
...

Sheet Mesh Independence Check
A1: Mesh Independence Check
A2: Method: consecutive-mesh percent difference, per Mohammed et al. (2022) Table 4 — NOT Richardson extrapolation / Celik GCI. Threshold: 2% (per the published paper; the thesis proposal draft states 1% but its own Table 13 doesn't reconcile internally, so 2% from the verified published source is used here).
A4: Nusselt Number (Nu) -- Monitor #1
A5: Mesh | B5: Elements | C5: Value | D5: % diff vs. previous mesh
A6: Mesh 1 (Coarsest) | B6: =IF('Mesh Run Data'!D17="","",'Mesh Run Data'!D17) -> 2718404 | C6: =IF('Mesh Run Data'!D43="","",'Mesh Run Data'!D43) -> 921.48745 | D6: —
A7: Mesh 2 | B7: =IF('Mesh Run Data'!E17="","",'Mesh Run Data'!E17) -> 4888550 | C7: =IF('Mesh Run Data'!E43="","",'Mesh Run Data'!E43) -> 927.35419 | D7: =IFERROR(IF(OR($C$7="",$C$6=""),"",ABS($C$7-$C$6)/$C$7*100),"") -> 0.63263116
A8: Mesh 3 | B8: =IF('Mesh Run Data'!F17="","",'Mesh Run Data'!F17) -> 8658088 | C8: =IF('Mesh Run Data'!F43="","",'Mesh Run Data'!F43) -> 909.12468 | D8: =IFERROR(IF(OR($C$8="",$C$7=""),"",ABS($C$8-$C$7)/$C$8*100),"") -> 2.0051716
A9: Mesh 4 (Finest) | B9: =IF('Mesh Run Data'!G17="","",'Mesh Run Data'!G17) -> 15675184 | C9: =IF('Mesh Run Data'!G43="","",'Mesh Run Data'!G43) -> 898.40356 | D9: =IFERROR(IF(OR($C$9="",$C$8=""),"",ABS($C$9-$C$8)/$C$9*100),"") -> 1.1933522
A10: Verdict | B10: =IFERROR(IF(OR($C$9="",$C$8=""),"Mesh 4 not yet entered -- generate and solve it, then re-check",IF(ABS($C$9-$C$8)/$C$9*100<2,"PASS -- Mesh 3 vs Mesh 4 within "&2&"% -- mesh independent","NOT YET -- Mesh 3 vs Mesh 4 exceeds "&2&"% -- refine further")),"Mesh 4 not yet entered -- generate and solve it, then re-check") -> PASS -- Mesh 3 vs Mesh 4 within 2% -- mesh independent
A12: Pressure Drop (ΔP) -- Monitor #2
A13: Mesh | B13: Elements | C13: Value | D13: % diff vs. previous mesh
A14: Mesh 1 (Coarsest) | B14: =IF('Mesh Run Data'!D17="","",'Mesh Run Data'!D17) -> 2718404 | C14: =IF('Mesh Run Data'!D32="","",'Mesh Run Data'!D32) -> 3604.2315 | D14: —
A15: Mesh 2 | B15: =IF('Mesh Run Data'!E17="","",'Mesh Run Data'!E17) -> 4888550 | C15: =IF('Mesh Run Data'!E32="","",'Mesh Run Data'!E32) -> 3551.4899 | D15: =IFERROR(IF(OR($C$15="",$C$14=""),"",ABS($C$15-$C$14)/$C$15*100),"") -> 1.4850556
A16: Mesh 3 | B16: =IF('Mesh Run Data'!F17="","",'Mesh Run Data'!F17) -> 8658088 | C16: =IF('Mesh Run Data'!F32="","",'Mesh Run Data'!F32) -> 3443.4149 | D16: =IFERROR(IF(OR($C$16="",$C$15=""),"",ABS($C$16-$C$15)/$C$16*100),"") -> 3.1385994
A17: Mesh 4 (Finest) | B17: =IF('Mesh Run Data'!G17="","",'Mesh Run Data'!G17) -> 15675184 | C17: =IF('Mesh Run Data'!G32="","",'Mesh Run Data'!G32) -> 3480.9322 | D17: =IFERROR(IF(OR($C$17="",$C$16=""),"",ABS($C$17-$C$16)/$C$17*100),"") -> 1.0777946
A18: Verdict | B18: =IFERROR(IF(OR($C$17="",$C$16=""),"Mesh 4 not yet entered -- generate and solve it, then re-check",IF(ABS($C$17-$C$16)/$C$17*100<2,"PASS -- Mesh 3 vs Mesh 4 within "&2&"% -- mesh independent","NOT YET -- Mesh 3 vs Mesh 4 exceeds "&2&"% -- refine further")),"Mesh 4 not yet entered -- generate and solve it, then re-check") -> PASS -- Mesh 3 vs Mesh 4 within 2% -- mesh independent
A20: Mesh independence is declared once BOTH Nu and ΔP clear the 2% bar between the two finest mesh levels -- matching Mohammed et al. (2022) Table 4's own acceptance practice (they adopted Mesh 3 of 4, not the finest, the moment it cleared their threshold).

Sheet Report Definition Reference
A1: Report Definition Reference
A2: Descriptive lookup — not for data entry. See 'Mesh Run Data' to fill in numbers.
A4: Quantity | B4: Category | C4: Report Type | D4: Field Variable | E4: Surface / Zone | F4: Units | G4: Monitor? | H4: Notes
A5: TEMPERATURE
A6: T_in | B6: Surface | C6: Mass-Weighted Avg | D6: Static Temperature | E6: both inlet faces (blended) | F6: K | G6: Yes | H6: Feeds Re, ΔT
A7: T_out | B7: Surface | C7: Mass-Weighted Avg | D7: Static Temperature | E7: both outlet faces (blended) | F7: K | G7: Yes | H7: Feeds Q̇_u, η_th
A8: T_ri (wall) | B8: Surface | C8: Area-Weighted Avg | D8: Static Temperature | E8: tube_wall_inner_interface | F8: K | G8: Yes | H8: Feeds h
A9: T_wall,max | B9: Surface | C9: Facet Maximum | D9: Static Temperature | E9: absorber_wall_lower/upper | F9: K | G9: No | H9: Thermal-stress discussion
A10: Wall T uniformity | B10: Surface | C10: Standard Deviation | D10: Static Temperature | E10: absorber_wall_lower | F10: K | G10: No | H10: Uniformity claim
A11: PRESSURE & FLOW
A12: p_in / p_out | B12: Surface | C12: Area-Weighted Avg | D12: Static Pressure | E12: inlet / outlet faces (blended) | F12: Pa | G12: Yes | H12: Feeds ΔP
A13: ṁ (mass flow) | B13: Surface / Flux | C13: Mass Flow Rate | D13: — | E13: inlet & outlet, separately | F13: kg/s | G13: Yes | H13: Mass-balance convergence check
A14: V̇ (volume flow) | B14: Surface | C14: Flow Rate | D14: — | E14: inlet | F14: m³/s | G14: No | H14: Feeds pumping power P_p
A15: τ_w (wall shear) | B15: Surface | C15: Area-Weighted Avg | D15: Wall Fluxes → Wall Shear Stress | E15: tube_wall_inner_interface | F15: Pa | G15: Yes | H15: Feeds f
A16: u_m (mean velocity) | B16: Derived | C16: Formula: mdot_in / (rho x A_total) | D16: — | E16: no Fluent surface needed | F16: m/s | G16: No | H16: A_total from dpo/tp geometry (exact -- twist doesn't change cross-sectional area)
A17: HEAT TRANSFER
A18: q'' (wall flux) | B18: Surface | C18: Area-Weighted Avg | D18: Wall Fluxes → Total Surface Heat Flux | E18: absorber_wall_lower/upper | F18: W/m² | G18: No | H18: BC check, feeds h
A19: Q̇ (total heat in) | B19: Flux | C19: Total Heat Transfer Rate | D19: — | E19: absorber_wall_lower + upper | F19: W | G19: Yes | H19: Energy-balance cross-check vs Q̇_u
A20: MESH / GCI
A21: Cell Count | B21: Mesh | C21: Cell Count | D21: — | E21: fluid_domain | F21: count | G21: No | H21: Per mesh level, before running
A22: y+ avg / max | B22: Surface | C22: Area-Wtd Avg / Facet Max | D22: Wall Fluxes → Wall Yplus | E22: tube_wall_inner_interface, highest Re | F22: — | G22: No | H22: Near-wall resolution check
A23: Skewness / orthogonal quality / aspect ratio | B23: N/A | C23: Not a Report Definition | D23: — | E23: — | F23: — | G23: No | H23: Read from Mesh → Quality panel directly

Sheet Figures & Output Parameters
A1: Figures & Output Parameters
A2: The tools that turn a converged case into thesis figures, plus when Create Output Parameter is worth using.
A4: Visualization tools
A5: Tool | B5: Answers the question | C5: What to use it on | D5: Thesis use
A6: Contours | B6: Where is this value high/low in space? | C6: A cross-sectional plane you slice through the fluid domain | D6: Temperature spread, wall hot spots
A7: Vectors | B7: Which way and how fast is the fluid moving? | C7: Cross-sectional plane, perpendicular to main flow | D7: Proof of secondary swirl from the promoter — your key mechanism figure
A8: Streamlines / Pathlines | B8: What path does the fluid take? | C8: Released from the inlet, traced through the geometry | D8: Visualizes the helical path around the twisted promoter
A9: XY Plot — Nu vs. axial position | B9: How does Nu change along the tube? | C9: A line along the tube's length | D9: Shows entrance-region effect (developing vs. fully developed flow)
A10: XY Plot — Nu vs. Re | B10: Does my Nu match the literature correlation? | C10: Your computed Nu at each Re, plus the Gnielinski curve | D10: Validation figure
A13: Create Output Parameter — do you need it?
A14: What it is: promotes a Report Definition so ANSYS Workbench can see it at the project level, across multiple linked simulations — not just inside this one Fluent session.
A15: Right now (GCI phase, 3 mesh levels, single geometry): NOT needed. This workbook — you typing converged values into 'Mesh Run Data' — is simpler and sufficient. No Workbench automation is running yet.
A16: Later (27-run Taguchi phase): genuinely useful. If Pt, dpo, tp are set up as Workbench input parameters and Nu/f as output parameters, Workbench can drive the sweep automatically — changing inputs, re-meshing, re-solving, and collecting results into one project-level table (its 'Design Point' table) without you manually rebuilding each case.
A17: "One big file that updates every run" — the honest answer: for 3 runs, manual entry into this workbook (Mesh Run Data tab) is the correct, reliable method — not worth automating. For the 27-run phase, Workbench's Parameter Set + Design Point table IS that auto-updating master file — each completed run appends its own row automatically. That gets set up when the 27-run phase actually starts, not before.
